Workbook

Sheet 2025
A1: JANEIRO | G1: FEVEREIRO | M1: MARÇO | S1: ABRIL | Y1: MAIO | AE1: JUNHO | AK1: JULHO | AQ1: AGOSTO | AW1: SETEMBRO | BC1: OUTUBRO | BI1: NOVEMBRO | BO1: DEZEMBRO
A2: Data | B2: Entrada | C2: Saída | D2: Diário | E2: Saldo | G2: Data | H2: Entrada | I2: Saída | J2: Diário | K2: Saldo | M2: Data | N2: Entrada | O2: Saída | P2: Diário | Q2: Saldo | S2: Data | T2: Entrada | U2: Saída | V2: Diário | W2: Saldo | Y2: Data | Z2: Entrada | AA2: Saída | AB2: Diário | AC2: Saldo | AE2: Data | AF2: Entrada | AG2: Saída | AH2: Diário | AI2: Saldo | AK2: Data | AL2: Entrada | AM2: Saída | AN2: Diário | AO2: Saldo | AQ2: Data | AR2: Entrada | AS2: Saída | AT2: Diário | AU2: Saldo | AW2: Data | AX2: Entrada | AY2: Saída | AZ2: Diário | BA2: Saldo | BC2: Data | BD2: Entrada | BE2: Saída | BF2: Diário | BG2: Saldo | BI2: Data | BJ2: Entrada | BK2: Saída | BL2: Diário | BM2: Saldo | BO2: Data | BP2: Entrada | BQ2: Saída | BR2: Diário | BS2: Saldo
A3: 1 | E3: =(B3)-(C3+D3) -> 0 | G3: 1 | K3: =(E33)+(H3)-(I3+J3) -> 0 | M3: 1 | Q3: =(K33)+(N3)-(O3+P3) -> 0 | S3: 1 | W3: =(Q33)+(T3)-(U3+V3) -> 0 | Y3: 1 | AC3: =(W33)+(Z3)-(AA3+AB3) -> 0 | AE3: 1 | AI3: =(AC33)+(AF3)-(AG3+AH3) -> 0 | AK3: 1 | AO3: =(AI33)+(AL3)-(AM3+AN3) -> 0 | AQ3: 1 | AU3: =(AO33)+(AR3)-(AS3+AT3) -> 0 | AW3: 1 | BA3: =(AU33)+(AX3)-(AY3+AZ3) -> 0 | BC3: 1 | BG3: =(BA33)+(BD3)-(BE3+BF3) -> 0 | BI3: 1 | BM3: =(BG33)+(BJ3)-(BK3+BL3) -> 0 | BO3: 1 | BP3: =266+270+200 -> 736 | BQ3: =450 -> 450 | BR3: =100+100+19.9+12+9.9+16.98+380+144.54+34.59+266+270+270 -> 1623.91 | BS3: =(BM33)+(BP3)-(BQ3+BR3) -> 5152.14
A4: 2 | E4: =(E3)+(B4)-(C4+D4) -> 0 | G4: 2 | K4: =(K3)+(H4)-(I4+J4) -> 0 | M4: 2 | Q4: =(Q3)+(N4)-(O4+P4) -> 0 | S4: 2 | W4: =(W3)+(T4)-(U4+V4) -> 0 | Y4: 2 | AC4: =(AC3)+(Z4)-(AA4+AB4) -> 0 | AE4: 2 | AI4: =(AI3)+(AF4)-(AG4+AH4) -> 0 | AK4: 2 | AO4: =(AO3)+(AL4)-(AM4+AN4) -> 0 | AQ4: 2 | AU4: =(AU3)+(AR4)-(AS4+AT4) -> 0 | AW4: 2 | BA4: =(BA3)+(AX4)-(AY4+AZ4) -> 0 | BC4: 2 | BG4: =(BG3)+(BD4)-(BE4+BF4) -> 0 | BI4: 2 | BM4: =(BM3)+(BJ4)-(BK4+BL4) -> 0 | BO4: 2 | BR4: =9.5+17.5 -> 27 | BS4: =(BS3)+(BP4)-(BQ4+BR4) -> 5125.14
A5: 3 | E5: =(E4)+(B5)-(C5+D5) -> 0 | G5: 3 | K5: =(K4)+(H5)-(I5+J5) -> 0 | M5: 3 | Q5: =(Q4)+(N5)-(O5+P5) -> 0 | S5: 3 | W5: =(W4)+(T5)-(U5+V5) -> 0 | Y5: 3 | AC5: =(AC4)+(Z5)-(AA5+AB5) -> 0 | AE5: 3 | AI5: =(AI4)+(AF5)-(AG5+AH5) -> 0 | AK5: 3 | AO5: =(AO4)+(AL5)-(AM5+AN5) -> 0 | AQ5: 3 | AU5: =(AU4)+(AR5)-(AS5+AT5) -> 0 | AW5: 3 | BA5: =(BA4)+(AX5)-(AY5+AZ5) -> 0 | BC5: 3 | BG5: =(BG4)+(BD5)-(BE5+BF5) -> 0 | BI5: 3 | BM5: =(BM4)+(BJ5)-(BK5+BL5) -> 0 | BO5: 3 | BR5: =5+89 -> 94 | BS5: =(BS4)+(BP5)-(BQ5+BR5) -> 5031.14
A6: 4 | E6: =(E5)+(B6)-(C6+D6) -> 0 | G6: 4 | K6: =(K5)+(H6)-(I6+J6) -> 0 | M6: 4 | Q6: =(Q5)+(N6)-(O6+P6) -> 0 | S6: 4 | W6: =(W5)+(T6)-(U6+V6) -> 0 | Y6: 4 | AC6: =(AC5)+(Z6)-(AA6+AB6) -> 0 | AE6: 4 | AI6: =(AI5)+(AF6)-(AG6+AH6) -> 0 | AK6: 4 | AO6: =(AO5)+(AL6)-(AM6+AN6) -> 0 | AQ6: 4 | AU6: =(AU5)+(AR6)-(AS6+AT6) -> 0 | AW6: 4 | BA6: =(BA5)+(AX6)-(AY6+AZ6) -> 0 | BC6: 4 | BG6: =(BG5)+(BD6)-(BE6+BF6) -> 0 | BI6: 4 | BM6: =(BM5)+(BJ6)-(BK6+BL6) -> 0 | BO6: 4 | BR6: =154.85 -> 154.85 | BS6: =(BS5)+(BP6)-(BQ6+BR6) -> 4876.29
A7: 5 | E7: =(E6)+(B7)-(C7+D7) -> 0 | G7: 5 | K7: =(K6)+(H7)-(I7+J7) -> 0 | M7: 5 | Q7: =(Q6)+(N7)-(O7+P7) -> 0 | S7: 5 | W7: =(W6)+(T7)-(U7+V7) -> 0 | Y7: 5 | AC7: =(AC6)+(Z7)-(AA7+AB7) -> 0 | AE7: 5 | AI7: =(AI6)+(AF7)-(AG7+AH7) -> 0 | AK7: 5 | AO7: =(AO6)+(AL7)-(AM7+AN7) -> 0 | AQ7: 5 | AU7: =(AU6)+(AR7)-(AS7+AT7) -> 0 | AW7: 5 | BA7: =(BA6)+(AX7)-(AY7+AZ7) -> 0 | BC7: 5 | BG7: =(BG6)+(BD7)-(BE7+BF7) -> 0 | BI7: 5 | BM7: =(BM6)+(BJ7)-(BK7+BL7) -> 0 | BO7: 5 | BR7: =154.85 -> 154.85 | BS7: =(BS6)+(BP7)-(BQ7+BR7) -> 4721.44
A8: 6 | E8: =(E7)+(B8)-(C8+D8) -> 0 | G8: 6 | K8: =(K7)+(H8)-(I8+J8) -> 0 | M8: 6 | Q8: =(Q7)+(N8)-(O8+P8) -> 0 | S8: 6 | W8: =(W7)+(T8)-(U8+V8) -> 0 | Y8: 6 | AC8: =(AC7)+(Z8)-(AA8+AB8) -> 0 | AE8: 6 | AI8: =(AI7)+(AF8)-(AG8+AH8) -> 0 | AK8: 6 | AO8: =(AO7)+(AL8)-(AM8+AN8) -> 0 | AQ8: 6 | AU8: =(AU7)+(AR8)-(AS8+AT8) -> 0 | AW8: 6 | BA8: =(BA7)+(AX8)-(AY8+AZ8) -> 0 | BC8: 6 | BG8: =(BG7)+(BD8)-(BE8+BF8) -> 0 | BI8: 6 | BM8: =(BM7)+(BJ8)-(BK8+BL8) -> 0 | BO8: 6 | BR8: =154.85 -> 154.85 | BS8: =(BS7)+(BP8)-(BQ8+BR8) -> 4566.59
A9: 7 | E9: =(E8)+(B9)-(C9+D9) -> 0 | G9: 7 | K9: =(K8)+(H9)-(I9+J9) -> 0 | M9: 7 | Q9: =(Q8)+(N9)-(O9+P9) -> 0 | S9: 7 | W9: =(W8)+(T9)-(U9+V9) -> 0 | Y9: 7 | AC9: =(AC8)+(Z9)-(AA9+AB9) -> 0 | AE9: 7 | AI9: =(AI8)+(AF9)-(AG9+AH9) -> 0 | AK9: 7 | AO9: =(AO8)+(AL9)-(AM9+AN9) -> 0 | AQ9: 7 | AU9: =(AU8)+(AR9)-(AS9+AT9) -> 0 | AW9: 7 | BA9: =(BA8)+(AX9)-(AY9+AZ9) -> 0 | BC9: 7 | BG9: =(BG8)+(BD9)-(BE9+BF9) -> 0 | BI9: 7 | BM9: =(BM8)+(BJ9)-(BK9+BL9) -> 0 | BO9: 7 | BR9: =154.85 -> 154.85 | BS9: =(BS8)+(BP9)-(BQ9+BR9) -> 4411.74
A10: 8 | E10: =(E9)+(B10)-(C10+D10) -> 0 | G10: 8 | K10: =(K9)+(H10)-(I10+J10) -> 0 | M10: 8 | Q10: =(Q9)+(N10)-(O10+P10) -> 0 | S10: 8 | W10: =(W9)+(T10)-(U10+V10) -> 0 | Y10: 8 | AC10: =(AC9)+(Z10)-(AA10+AB10) -> 0 | AE10: 8 | AI10: =(AI9)+(AF10)-(AG10+AH10) -> 0 | AK10: 8 | AO10: =(AO9)+(AL10)-(AM10+AN10) -> 0 | AQ10: 8 | AU10: =(AU9)+(AR10)-(AS10+AT10) -> 0 | AW10: 8 | BA10: =(BA9)+(AX10)-(AY10+AZ10) -> 0 | BC10: 8 | BG10: =(BG9)+(BD10)-(BE10+BF10) -> 0 | BI10: 8 | BM10: =(BM9)+(BJ10)-(BK10+BL10) -> 0 | BO10: 8 | BR10: =154.85 -> 154.85 | BS10: =(BS9)+(BP10)-(BQ10+BR10) -> 4256.89
A11: 9 | E11: =(E10)+(B11)-(C11+D11) -> 0 | G11: 9 | K11: =(K10)+(H11)-(I11+J11) -> 0 | M11: 9 | Q11: =(Q10)+(N11)-(O11+P11) -> 0 | S11: 9 | W11: =(W10)+(T11)-(U11+V11) -> 0 | Y11: 9 | AC11: =(AC10)+(Z11)-(AA11+AB11) -> 0 | AE11: 9 | AI11: =(AI10)+(AF11)-(AG11+AH11) -> 0 | AK11: 9 | AO11: =(AO10)+(AL11)-(AM11+AN11) -> 0 | AQ11: 9 | AU11: =(AU10)+(AR11)-(AS11+AT11) -> 0 | AW11: 9 | BA11: =(BA10)+(AX11)-(AY11+AZ11) -> 0 | BC11: 9 | BG11: =(BG10)+(BD11)-(BE11+BF11) -> 0 | BI11: 9 | BM11: =(BM10)+(BJ11)-(BK11+BL11) -> 0 | BO11: 9 | BR11: =154.85 -> 154.85 | BS11: =(BS10)+(BP11)-(BQ11+BR11) -> 4102.04
A12: 10 | E12: =(E11)+(B12)-(C12+D12) -> 0 | G12: 10 | K12: =(K11)+(H12)-(I12+J12) -> 0 | M12: 10 | Q12: =(Q11)+(N12)-(O12+P12) -> 0 | S12: 10 | W12: =(W11)+(T12)-(U12+V12) -> 0 | Y12: 10 | AC12: =(AC11)+(Z12)-(AA12+AB12) -> 0 | AE12: 10 | AI12: =(AI11)+(AF12)-(AG12+AH12) -> 0 | AK12: 10 | AO12: =(AO11)+(AL12)-(AM12+AN12) -> 0 | AQ12: 10 | AU12: =(AU11)+(AR12)-(AS12+AT12) -> 0 | AW12: 10 | BA12: =(BA11)+(AX12)-(AY12+AZ12) -> 0 | BC12: 10 | BG12: =(BG11)+(BD12)-(BE12+BF12) -> 0 | BI12: 10 | BJ12: 2425.63 | BL12: 0 | BM12: =(BM11)+(BJ12)-(BK12+BL12) -> 2425.63 | BO12: 10 | BQ12: =1881+100+160+60 -> 2201 | BR12: =154.85 -> 154.85 | BS12: =(BS11)+(BP12)-(BQ12+BR12) -> 1746.19
A13: 11 | E13: =(E12)+(B13)-(C13+D13) -> 0 | G13: 11 | K13: =(K12)+(H13)-(I13+J13) -> 0 | M13: 11 | Q13: =(Q12)+(N13)-(O13+P13) -> 0 | S13: 11 | W13: =(W12)+(T13)-(U13+V13) -> 0 | Y13: 11 | AC13: =(AC12)+(Z13)-(AA13+AB13) -> 0 | AE13: 11 | AI13: =(AI12)+(AF13)-(AG13+AH13) -> 0 | AK13: 11 | AO13: =(AO12)+(AL13)-(AM13+AN13) -> 0 | AQ13: 11 | AU13: =(AU12)+(AR13)-(AS13+AT13) -> 0 | AW13: 11 | BA13: =(BA12)+(AX13)-(AY13+AZ13) -> 0 | BC13: 11 | BG13: =(BG12)+(BD13)-(BE13+BF13) -> 0 | BI13: 11 | BL13: =150 -> 150 | BM13: =(BM12)+(BJ13)-(BK13+BL13) -> 2275.63 | BO13: 11 | BR13: =154.85 -> 154.85 | BS13: =(BS12)+(BP13)-(BQ13+BR13) -> 1591.34
A14: 12 | E14: =(E13)+(B14)-(C14+D14) -> 0 | G14: 12 | K14: =(K13)+(H14)-(I14+J14) -> 0 | M14: 12 | Q14: =(Q13)+(N14)-(O14+P14) -> 0 | S14: 12 | W14: =(W13)+(T14)-(U14+V14) -> 0 | Y14: 12 | AC14: =(AC13)+(Z14)-(AA14+AB14) -> 0 | AE14: 12 | AI14: =(AI13)+(AF14)-(AG14+AH14) -> 0 | AK14: 12 | AO14: =(AO13)+(AL14)-(AM14+AN14) -> 0 | AQ14: 12 | AU14: =(AU13)+(AR14)-(AS14+AT14) -> 0 | AW14: 12 | BA14: =(BA13)+(AX14)-(AY14+AZ14) -> 0 | BC14: 12 | BG14: =(BG13)+(BD14)-(BE14+BF14) -> 0 | BI14: 12 | BL14: 0 | BM14: =(BM13)+(BJ14)-(BK14+BL14) -> 2275.63 | BO14: 12 | BR14: =154.85 -> 154.85 | BS14: =(BS13)+(BP14)-(BQ14+BR14) -> 1436.49
A15: 13 | E15: =(E14)+(B15)-(C15+D15) -> 0 | G15: 13 | K15: =(K14)+(H15)-(I15+J15) -> 0 | M15: 13 | Q15: =(Q14)+(N15)-(O15+P15) -> 0 | S15: 13 | W15: =(W14)+(T15)-(U15+V15) -> 0 | Y15: 13 | AC15: =(AC14)+(Z15)-(AA15+AB15) -> 0 | AE15: 13 | AI15: =(AI14)+(AF15)-(AG15+AH15) -> 0 | AK15: 13 | AO15: =(AO14)+(AL15)-(AM15+AN15) -> 0 | AQ15: 13 | AU15: =(AU14)+(AR15)-(AS15+AT15) -> 0 | AW15: 13 | BA15: =(BA14)+(AX15)-(AY15+AZ15) -> 0 | BC15: 13 | BG15: =(BG14)+(BD15)-(BE15+BF15) -> 0 | BI15: 13 | BL15: =100+13.63+500 -> 613.63 | BM15: =(BM14)+(BJ15)-(BK15+BL15) -> 1662 | BO15: 13 | BR15: =154.85 -> 154.85 | BS15: =(BS14)+(BP15)-(BQ15+BR15) -> 1281.64
A16: 14 | E16: =(E15)+(B16)-(C16+D16) -> 0 | G16: 14 | K16: =(K15)+(H16)-(I16+J16) -> 0 | M16: 14 | Q16: =(Q15)+(N16)-(O16+P16) -> 0 | S16: 14 | W16: =(W15)+(T16)-(U16+V16) -> 0 | Y16: 14 | AC16: =(AC15)+(Z16)-(AA16+AB16) -> 0 | AE16: 14 | AI16: =(AI15)+(AF16)-(AG16+AH16) -> 0 | AK16: 14 | AO16: =(AO15)+(AL16)-(AM16+AN16) -> 0 | AQ16: 14 | AU16: =(AU15)+(AR16)-(AS16+AT16) -> 0 | AW16: 14 | BA16: =(BA15)+(AX16)-(AY16+AZ16) -> 0 | BC16: 14 | BG16: =(BG15)+(BD16)-(BE16+BF16) -> 0 | BI16: 14 | BL16: 0 | BM16: =(BM15)+(BJ16)-(BK16+BL16) -> 1662 | BO16: 14 | BR16: =154.85 -> 154.85 | BS16: =(BS15)+(BP16)-(BQ16+BR16) -> 1126.79
A17: 15 | E17: =(E16)+(B17)-(C17+D17) -> 0 | G17: 15 | K17: =(K16)+(H17)-(I17+J17) -> 0 | M17: 15 | Q17: =(Q16)+(N17)-(O17+P17) -> 0 | S17: 15 | W17: =(W16)+(T17)-(U17+V17) -> 0 | Y17: 15 | AC17: =(AC16)+(Z17)-(AA17+AB17) -> 0 | AE17: 15 | AI17: =(AI16)+(AF17)-(AG17+AH17) -> 0 | AK17: 15 | AO17: =(AO16)+(AL17)-(AM17+AN17) -> 0 | AQ17: 15 | AU17: =(AU16)+(AR17)-(AS17+AT17) -> 0 | AW17: 15 | BA17: =(BA16)+(AX17)-(AY17+AZ17) -> 0 | BC17: 15 | BG17: =(BG16)+(BD17)-(BE17+BF17) -> 0 | BI17: 15 | BL17: 30 | BM17: =(BM16)+(BJ17)-(BK17+BL17) -> 1632 | BO17: 15 | BQ17: =500 -> 500 | BR17: =154.85 -> 154.85 | BS17: =(BS16)+(BP17)-(BQ17+BR17) -> 471.94
A18: 16 | E18: =(E17)+(B18)-(C18+D18) -> 0 | G18: 16 | K18: =(K17)+(H18)-(I18+J18) -> 0 | M18: 16 | Q18: =(Q17)+(N18)-(O18+P18) -> 0 | S18: 16 | W18: =(W17)+(T18)-(U18+V18) -> 0 | Y18: 16 | AC18: =(AC17)+(Z18)-(AA18+AB18) -> 0 | AE18: 16 | AI18: =(AI17)+(AF18)-(AG18+AH18) -> 0 | AK18: 16 | AO18: =(AO17)+(AL18)-(AM18+AN18) -> 0 | AQ18: 16 | AU18: =(AU17)+(AR18)-(AS18+AT18) -> 0 | AW18: 16 | BA18: =(BA17)+(AX18)-(AY18+AZ18) -> 0 | BC18: 16 | BG18: =(BG17)+(BD18)-(BE18+BF18) -> 0 | BI18: 16 | BL18: 0 | BM18: =(BM17)+(BJ18)-(BK18+BL18) -> 1632 | BO18: 16 | BR18: =154.85 -> 154.85 | BS18: =(BS17)+(BP18)-(BQ18+BR18) -> 317.09
A19: 17 | E19: =(E18)+(B19)-(C19+D19) -> 0 | G19: 17 | K19: =(K18)+(H19)-(I19+J19) -> 0 | M19: 17 | Q19: =(Q18)+(N19)-(O19+P19) -> 0 | S19: 17 | W19: =(W18)+(T19)-(U19+V19) -> 0 | Y19: 17 | AC19: =(AC18)+(Z19)-(AA19+AB19) -> 0 | AE19: 17 | AI19: =(AI18)+(AF19)-(AG19+AH19) -> 0 | AK19: 17 | AO19: =(AO18)+(AL19)-(AM19+AN19) -> 0 | AQ19: 17 | AU19: =(AU18)+(AR19)-(AS19+AT19) -> 0 | AW19: 17 | BA19: =(BA18)+(AX19)-(AY19+AZ19) -> 0 | BC19: 17 | BG19: =(BG18)+(BD19)-(BE19+BF19) -> 0 | BI19: 17 | BL19: =40+5.49+10.25+30+10.25 -> 95.99 | BM19: =(BM18)+(BJ19)-(BK19+BL19) -> 1536.01 | BO19: 17 | BR19: =154.85 -> 154.85 | BS19: =(BS18)+(BP19)-(BQ19+BR19) -> 162.24
A20: 18 | E20: =(E19)+(B20)-(C20+D20) -> 0 | G20: 18 | K20: =(K19)+(H20)-(I20+J20) -> 0 | M20: 18 | Q20: =(Q19)+(N20)-(O20+P20) -> 0 | S20: 18 | W20: =(W19)+(T20)-(U20+V20) -> 0 | Y20: 18 | AC20: =(AC19)+(Z20)-(AA20+AB20) -> 0 | AE20: 18 | AI20: =(AI19)+(AF20)-(AG20+AH20) -> 0 | AK20: 18 | AO20: =(AO19)+(AL20)-(AM20+AN20) -> 0 | AQ20: 18 | AU20: =(AU19)+(AR20)-(AS20+AT20) -> 0 | AW20: 18 | BA20: =(BA19)+(AX20)-(AY20+AZ20) -> 0 | BC20: 18 | BG20: =(BG19)+(BD20)-(BE20+BF20) -> 0 | BI20: 18 | BL20: 0 | BM20: =(BM19)+(BJ20)-(BK20+BL20) -> 1536.01 | BO20: 18 | BR20: =154.85 -> 154.85 | BS20: =(BS19)+(BP20)-(BQ20+BR20) -> 7.39
A21: 19 | E21: =(E20)+(B21)-(C21+D21) -> 0 | G21: 19 | K21: =(K20)+(H21)-(I21+J21) -> 0 | M21: 19 | Q21: =(Q20)+(N21)-(O21+P21) -> 0 | S21: 19 | W21: =(W20)+(T21)-(U21+V21) -> 0 | Y21: 19 | AC21: =(AC20)+(Z21)-(AA21+AB21) -> 0 | AE21: 19 | AI21: =(AI20)+(AF21)-(AG21+AH21) -> 0 | AK21: 19 | AO21: =(AO20)+(AL21)-(AM21+AN21) -> 0 | AQ21: 19 | AU21: =(AU20)+(AR21)-(AS21+AT21) -> 0 | AW21: 19 | BA21: =(BA20)+(AX21)-(AY21+AZ21) -> 0 | BC21: 19 | BG21: =(BG20)+(BD21)-(BE21+BF21) -> 0 | BI21: 19 | BL21: =13+150+100 -> 263 | BM21: =(BM20)+(BJ21)-(BK21+BL21) -> 1273.01 | BO21: 19 | BR21: =154.85 -> 154.85 | BS21: =(BS20)+(BP21)-(BQ21+BR21) -> -147.46
A22: 20 | E22: =(E21)+(B22)-(C22+D22) -> 0 | G22: 20 | K22: =(K21)+(H22)-(I22+J22) -> 0 | M22: 20 | Q22: =(Q21)+(N22)-(O22+P22) -> 0 | S22: 20 | W22: =(W21)+(T22)-(U22+V22) -> 0 | Y22: 20 | AC22: =(AC21)+(Z22)-(AA22+AB22) -> 0 | AE22: 20 | AI22: =(AI21)+(AF22)-(AG22+AH22) -> 0 | AK22: 20 | AO22: =(AO21)+(AL22)-(AM22+AN22) -> 0 | AQ22: 20 | AU22: =(AU21)+(AR22)-(AS22+AT22) -> 0 | AW22: 20 | BA22: =(BA21)+(AX22)-(AY22+AZ22) -> 0 | BC22: 20 | BG22: =(BG21)+(BD22)-(BE22+BF22) -> 0 | BI22: 20 | BL22: 0 | BM22: =(BM21)+(BJ22)-(BK22+BL22) -> 1273.01 | BO22: 20 | BR22: =154.85 -> 154.85 | BS22: =(BS21)+(BP22)-(BQ22+BR22) -> -302.31
A23: 21 | E23: =(E22)+(B23)-(C23+D23) -> 0 | G23: 21 | K23: =(K22)+(H23)-(I23+J23) -> 0 | M23: 21 | Q23: =(Q22)+(N23)-(O23+P23) -> 0 | S23: 21 | W23: =(W22)+(T23)-(U23+V23) -> 0 | Y23: 21 | AC23: =(AC22)+(Z23)-(AA23+AB23) -> 0 | AE23: 21 | AI23: =(AI22)+(AF23)-(AG23+AH23) -> 0 | AK23: 21 | AO23: =(AO22)+(AL23)-(AM23+AN23) -> 0 | AQ23: 21 | AU23: =(AU22)+(AR23)-(AS23+AT23) -> 0 | AW23: 21 | BA23: =(BA22)+(AX23)-(AY23+AZ23) -> 0 | BC23: 21 | BG23: =(BG22)+(BD23)-(BE23+BF23) -> 0 | BI23: 21 | BJ23: =17873.9+2380 -> 20253.9 | BL23: =100+11.99+39.58+192.19+231.82+19.98+30+1100+86.67 -> 1812.23 | BM23: =(BM22)+(BJ23)-(BK23+BL23) -> 19714.68 | BO23: 21 | BP23: 17800 | BR23: =154.85 -> 154.85 | BS23: =(BS22)+(BP23)-(BQ23+BR23) -> 17342.84
A24: 22 | E24: =(E23)+(B24)-(C24+D24) -> 0 | G24: 22 | K24: =(K23)+(H24)-(I24+J24) -> 0 | M24: 22 | Q24: =(Q23)+(N24)-(O24+P24) -> 0 | S24: 22 | W24: =(W23)+(T24)-(U24+V24) -> 0 | Y24: 22 | AC24: =(AC23)+(Z24)-(AA24+AB24) -> 0 | AE24: 22 | AI24: =(AI23)+(AF24)-(AG24+AH24) -> 0 | AK24: 22 | AO24: =(AO23)+(AL24)-(AM24+AN24) -> 0 | AQ24: 22 | AU24: =(AU23)+(AR24)-(AS24+AT24) -> 0 | AW24: 22 | BA24: =(BA23)+(AX24)-(AY24+AZ24) -> 0 | BC24: 22 | BG24: =(BG23)+(BD24)-(BE24+BF24) -> 0 | BI24: 22 | BL24: 0 | BM24: =(BM23)+(BJ24)-(BK24+BL24) -> 19714.68 | BO24: 22 | BR24: =154.85 -> 154.85 | BS24: =(BS23)+(BP24)-(BQ24+BR24) -> 17187.99
A25: 23 | E25: =(E24)+(B25)-(C25+D25) -> 0 | G25: 23 | K25: =(K24)+(H25)-(I25+J25) -> 0 | M25: 23 | Q25: =(Q24)+(N25)-(O25+P25) -> 0 | S25: 23 | W25: =(W24)+(T25)-(U25+V25) -> 0 | Y25: 23 | AC25: =(AC24)+(Z25)-(AA25+AB25) -> 0 | AE25: 23 | AI25: =(AI24)+(AF25)-(AG25+AH25) -> 0 | AK25: 23 | AO25: =(AO24)+(AL25)-(AM25+AN25) -> 0 | AQ25: 23 | AU25: =(AU24)+(AR25)-(AS25+AT25) -> 0 | AW25: 23 | BA25: =(BA24)+(AX25)-(AY25+AZ25) -> 0 | BC25: 23 | BG25: =(BG24)+(BD25)-(BE25+BF25) -> 0 | BI25: 23 | BK25: =178.69+379.8 -> 558.49 | BL25: 0 | BM25: =(BM24)+(BJ25)-(BK25+BL25) -> 19156.19 | BO25: 23 | BQ25: =178.69+379.8 -> 558.49 | BR25: =154.85 -> 154.85 | BS25: =(BS24)+(BP25)-(BQ25+BR25) -> 16474.65
A26: 24 | E26: =(E25)+(B26)-(C26+D26) -> 0 | G26: 24 | K26: =(K25)+(H26)-(I26+J26) -> 0 | M26: 24 | Q26: =(Q25)+(N26)-(O26+P26) -> 0 | S26: 24 | W26: =(W25)+(T26)-(U26+V26) -> 0 | Y26: 24 | AC26: =(AC25)+(Z26)-(AA26+AB26) -> 0 | AE26: 24 | AI26: =(AI25)+(AF26)-(AG26+AH26) -> 0 | AK26: 24 | AO26: =(AO25)+(AL26)-(AM26+AN26) -> 0 | AQ26: 24 | AU26: =(AU25)+(AR26)-(AS26+AT26) -> 0 | AW26: 24 | BA26: =(BA25)+(AX26)-(AY26+AZ26) -> 0 | BC26: 24 | BG26: =(BG25)+(BD26)-(BE26+BF26) -> 0 | BI26: 24 | BJ26: 65 | BK26: =522.59+4220.62+1572.16+27+133.5+147.36+27+72+27.97+94.47+163.06+26+197.41 -> 7231.14 | BL26: =100+280+50+7 -> 437 | BM26: =(BM25)+(BJ26)-(BK26+BL26) -> 11553.05 | BO26: 24 | BQ26: =167.01+905.91+333.16+74.87+27+68.2+23.1+35.38+46.3+65.62+213.88+20.68+105.98+48+116.27+17.67+74.48+156.6+134.04+162.77+79.1+57.9+100+49.9+156.5+27+23.4+36.36+46.19+146.53+48.85+119.92+27+31.69+2.94+24.3+120+17+187.99+32.37+85.42+37.82+32+190.5+116.82+53.8+474.7+47.3+106.89+254.4+95.8+120+109.98+125.99+223.71+29.75+39.87+33.4+19.9+48.85+10.92+78.24+76.39 -> 6544.31 | BR26: =154.85 -> 154.85 | BS26: =(BS25)+(BP26)-(BQ26+BR26) -> 9775.49
A27: 25 | E27: =(E26)+(B27)-(C27+D27) -> 0 | G27: 25 | K27: =(K26)+(H27)-(I27+J27) -> 0 | M27: 25 | Q27: =(Q26)+(N27)-(O27+P27) -> 0 | S27: 25 | W27: =(W26)+(T27)-(U27+V27) -> 0 | Y27: 25 | AC27: =(AC26)+(Z27)-(AA27+AB27) -> 0 | AE27: 25 | AI27: =(AI26)+(AF27)-(AG27+AH27) -> 0 | AK27: 25 | AO27: =(AO26)+(AL27)-(AM27+AN27) -> 0 | AQ27: 25 | AU27: =(AU26)+(AR27)-(AS27+AT27) -> 0 | AW27: 25 | BA27: =(BA26)+(AX27)-(AY27+AZ27) -> 0 | BC27: 25 | BG27: =(BG26)+(BD27)-(BE27+BF27) -> 0 | BI27: 25 | BK27: =287.84-31.23 -> 256.61 | BL27: =50+28.94+100 -> 178.94 | BM27: =(BM26)+(BJ27)-(BK27+BL27) -> 11117.5 | BO27: 25 | BR27: =154.85 -> 154.85 | BS27: =(BS26)+(BP27)-(BQ27+BR27) -> 9620.64
A28: 26 | E28: =(E27)+(B28)-(C28+D28) -> 0 | G28: 26 | K28: =(K27)+(H28)-(I28+J28) -> 0 | M28: 26 | Q28: =(Q27)+(N28)-(O28+P28) -> 0 | S28: 26 | W28: =(W27)+(T28)-(U28+V28) -> 0 | Y28: 26 | AC28: =(AC27)+(Z28)-(AA28+AB28) -> 0 | AE28: 26 | AI28: =(AI27)+(AF28)-(AG28+AH28) -> 0 | AK28: 26 | AO28: =(AO27)+(AL28)-(AM28+AN28) -> 0 | AQ28: 26 | AU28: =(AU27)+(AR28)-(AS28+AT28) -> 0 | AW28: 26 | BA28: =(BA27)+(AX28)-(AY28+AZ28) -> 0 | BC28: 26 | BG28: =(BG27)+(BD28)-(BE28+BF28) -> 0 | BI28: 26 | BJ28: =130+130+65 -> 325 | BK28: =4230+103+30+110+45 -> 4518 | BL28: 0 | BM28: =(BM27)+(BJ28)-(BK28+BL28) -> 6924.5 | BO28: 26 | BQ28: =4230+103+30+110+45 -> 4518 | BR28: =154.85 -> 154.85 | BS28: =(BS27)+(BP28)-(BQ28+BR28) -> 4947.79
A29: 27 | E29: =(E28)+(B29)-(C29+D29) -> 0 | G29: 27 | K29: =(K28)+(H29)-(I29+J29) -> 0 | M29: 27 | Q29: =(Q28)+(N29)-(O29+P29) -> 0 | S29: 27 | W29: =(W28)+(T29)-(U29+V29) -> 0 | Y29: 27 | AC29: =(AC28)+(Z29)-(AA29+AB29) -> 0 | AE29: 27 | AI29: =(AI28)+(AF29)-(AG29+AH29) -> 0 | AK29: 27 | AO29: =(AO28)+(AL29)-(AM29+AN29) -> 0 | AQ29: 27 | AU29: =(AU28)+(AR29)-(AS29+AT29) -> 0 | AW29: 27 | BA29: =(BA28)+(AX29)-(AY29+AZ29) -> 0 | BC29: 27 | BG29: =(BG28)+(BD29)-(BE29+BF29) -> 0 | BI29: 27 | BL29: =50+6.65+150 -> 206.65 | BM29: =(BM28)+(BJ29)-(BK29+BL29) -> 6717.85 | BO29: 27 | BR29: =154.85 -> 154.85 | BS29: =(BS28)+(BP29)-(BQ29+BR29) -> 4792.94
A30: 28 | E30: =(E29)+(B30)-(C30+D30) -> 0 | G30: 28 | K30: =(K29)+(H30)-(I30+J30) -> 0 | M30: 28 | Q30: =(Q29)+(N30)-(O30+P30) -> 0 | S30: 28 | W30: =(W29)+(T30)-(U30+V30) -> 0 | Y30: 28 | AC30: =(AC29)+(Z30)-(AA30+AB30) -> 0 | AE30: 28 | AI30: =(AI29)+(AF30)-(AG30+AH30) -> 0 | AK30: 28 | AO30: =(AO29)+(AL30)-(AM30+AN30) -> 0 | AQ30: 28 | AU30: =(AU29)+(AR30)-(AS30+AT30) -> 0 | AW30: 28 | BA30: =(BA29)+(AX30)-(AY30+AZ30) -> 0 | BC30: 28 | BG30: =(BG29)+(BD30)-(BE30+BF30) -> 0 | BI30: 28 | BL30: =100+100+5.49+22.31 -> 227.8 | BM30: =(BM29)+(BJ30)-(BK30+BL30) -> 6490.05 | BO30: 28 | BR30: =154.85 -> 154.85 | BS30: =(BS29)+(BP30)-(BQ30+BR30) -> 4638.09
A31: 29 | E31: =(E30)+(B31)-(C31+D31) -> 0 | G31: 29 | K31: =(K30)+(H31)-(I31+J31) -> 0 | M31: 29 | Q31: =(Q30)+(N31)-(O31+P31) -> 0 | S31: 29 | W31: =(W30)+(T31)-(U31+V31) -> 0 | Y31: 29 | AC31: =(AC30)+(Z31)-(AA31+AB31) -> 0 | AE31: 29 | AI31: =(AI30)+(AF31)-(AG31+AH31) -> 0 | AK31: 29 | AO31: =(AO30)+(AL31)-(AM31+AN31) -> 0 | AQ31: 29 | AU31: =(AU30)+(AR31)-(AS31+AT31) -> 0 | AW31: 29 | BA31: =(BA30)+(AX31)-(AY31+AZ31) -> 0 | BC31: 29 | BG31: =(BG30)+(BD31)-(BE31+BF31) -> 0 | BI31: 29 | BL31: 0 | BM31: =(BM30)+(BJ31)-(BK31+BL31) -> 6490.05 | BO31: 29 | BR31: =154.85 -> 154.85 | BS31: =(BS30)+(BP31)-(BQ31+BR31) -> 4483.24
A32: 30 | E32: =(E31)+(B32)-(C32+D32) -> 0 | G32: 30 | K32: =(K31)+(H32)-(I32+J32) -> 0 | M32: 30 | Q32: =(Q31)+(N32)-(O32+P32) -> 0 | S32: 30 | W32: =(W31)+(T32)-(U32+V32) -> 0 | Y32: 30 | AC32: =(AC31)+(Z32)-(AA32+AB32) -> 0 | AE32: 30 | AI32: =(AI31)+(AF32)-(AG32+AH32) -> 0 | AK32: 30 | AO32: =(AO31)+(AL32)-(AM32+AN32) -> 0 | AQ32: 30 | AU32: =(AU31)+(AR32)-(AS32+AT32) -> 0 | AW32: 30 | BA32: =(BA31)+(AX32)-(AY32+AZ32) -> 0 | BC32: 30 | BG32: =(BG31)+(BD32)-(BE32+BF32) -> 0 | BI32: 30 | BL32: 0 | BM32: =(BM31)+(BJ32)-(BK32+BL32) -> 6490.05 | BO32: 30 | BR32: =154.85 -> 154.85 | BS32: =(BS31)+(BP32)-(BQ32+BR32) -> 4328.39
A33: 31 | E33: =(E32)+(B33)-(C33+D33) -> 0 | G33: 31 | K33: =(K32)+(H33)-(I33+J33) -> 0 | M33: 31 | Q33: =(Q32)+(N33)-(O33+P33) -> 0 | S33: 31 | W33: =(W32)+(T33)-(U33+V33) -> 0 | Y33: 31 | AC33: =(AC32)+(Z33)-(AA33+AB33) -> 0 | AE33: 31 | AI33: =(AI32)+(AF33)-(AG33+AH33) -> 0 | AK33: 31 | AO33: =(AO32)+(AL33)-(AM33+AN33) -> 0 | AQ33: 31 | AU33: =(AU32)+(AR33)-(AS33+AT33) -> 0 | AW33: 31 | BA33: =(BA32)+(AX33)-(AY33+AZ33) -> 0 | BC33: 31 | BG33: =(BG32)+(BD33)-(BE33+BF33) -> 0 | BI33: 31 | BL33: 0 | BM33: =(BM32)+(BJ33)-(BK33+BL33) -> 6490.05 | BO33: 31 | BR33: =154.85 -> 154.85 | BS33: =(BS32)+(BP33)-(BQ33+BR33) -> 4173.54
B37: ENTRADAS | C37: SAÍDAS | D37: DIÁRIO | H37: ENTRADAS | I37: SAÍDAS | J37: DIÁRIO | N37: ENTRADAS | O37: SAÍDAS | P37: DIÁRIO | T37: ENTRADAS | U37: SAÍDAS | V37: DIÁRIO | Z37: ENTRADAS | AA37: SAÍDAS | AB37: DIÁRIO | AF37: ENTRADAS | AG37: SAÍDAS | AH37: DIÁRIO | AL37: ENTRADAS | AM37: SAÍDAS | AN37: DIÁRIO | AR37: ENTRADAS | AS37: SAÍDAS | AT37: DIÁRIO | AX37: ENTRADAS | AY37: SAÍDAS | AZ37: DIÁRIO | BD37: ENTRADAS | BE37: SAÍDAS | BF37: DIÁRIO | BJ37: ENTRADAS | BK37: SAÍDAS | BL37: DIÁRIO | BP37: ENTRADAS | BQ37: SAÍDAS | BR37: DIÁRIO
B38: =SUM(B3:B33) -> 0 | C38: =SUM(C3:C33) -> 0 | D38: =SUM(D3:D33) -> 0 | E38: =E34 | H38: =SUM(H3:H33) -> 0 | I38: =SUM(I3:I33) -> 0 | J38: =SUM(J3:J33) -> 0 | K38: =K34 | N38: =SUM(N3:N33) -> 0 | O38: =SUM(O3:O33) -> 0 | P38: =SUM(P3:P33) -> 0 | Q38: =Q34 | T38: =SUM(T3:T33) -> 0 | U38: =SUM(U3:U33) -> 0 | V38: =SUM(V3:V33) -> 0 | W38: =W34 | Z38: =SUM(Z3:Z33) -> 0 | AA38: =SUM(AA3:AA33) -> 0 | AB38: =SUM(AB3:AB33) -> 0 | AC38: =AC34 | AF38: =SUM(AF3:AF33) -> 0 | AG38: =SUM(AG3:AG33) -> 0 | AH38: =SUM(AH3:AH33) -> 0 | AI38: =AI34 | AL38: =SUM(AL3:AL33) -> 0 | AM38: =SUM(AM3:AM33) -> 0 | AN38: =SUM(AN3:AN33) -> 0 | AO38: =AO34 | AR38: =SUM(AR3:AR33) -> 0 | AS38: =SUM(AS3:AS33) -> 0 | AT38: =SUM(AT3:AT33) -> 0 | AU38: =AU34 | AX38: =SUM(AX3:AX33) -> 0 | AY38: =SUM(AY3:AY33) -> 0 | AZ38: =SUM(AZ3:AZ33) -> 0 | BA38: =BA34 | BD38: =SUM(BD3:BD33) -> 0 | BE38: =SUM(BE3:BE33) -> 0 | BF38: =SUM(BF3:BF33) -> 0 | BG38: =BG34 | BJ38: =SUM(BJ3:BJ33) -> 23069.53 | BK38: =SUM(BK3:BK33) -> 12564.24 | BL38: =SUM(BL3:BL33) -> 4015.24 | BM38: =BM34 | BP38: =SUM(BP3:BP33) -> 18536 | BQ38: =SUM(BQ3:BQ33) -> 14771.8 | BR38: =SUM(BR3:BR33) -> 6080.71 | BS38: =BS34
D40: Saída Total | J40: Saída Total | P40: Saída Total | V40: Saída Total | AB40: Saída Total | AH40: Saída Total | AN40: Saída Total | AT40: Saída Total | AZ40: Saída Total | BF40: Saída Total | BL40: Saída Total | BR40: Saída Total
D41: =C38+D38 -> 0 | J41: =I38+J38 -> 0 | P41: =O38+P38 -> 0 | V41: =U38+V38 -> 0 | AB41: =AA38+AB38 -> 0 | AH41: =AG38+AH38 -> 0 | AN41: =AM38+AN38 -> 0 | AT41: =AS38+AT38 -> 0 | AZ41: =AY38+AZ38 -> 0 | BF41: =BE38+BF38 -> 0 | BL41: =BK38+BL38 -> 16579.48 | BR41: =BQ38+BR38 -> 20852.51
D43: Performance | J43: Performance | P43: Performance | V43: Performance | AB43: Performance | AH43: Performance | AN43: Performance | AT43: Performance | AZ43: Performance | BF43: Performance | BL43: Performance | BR43: Performance
D44: =B38-D41 -> 0 | J44: =H38-J41 -> 0 | P44: =N38-P41 -> 0 | V44: =T38-V41 -> 0 | AB44: =Z38-AB41 -> 0 | AH44: =AF38-AH41 -> 0 | AN44: =AL38-AN41 -> 0 | AT44: =AR38-AT41 -> 0 | AZ44: =AX38-AZ41 -> 0 | BF44: =BD38-BF41 -> 0 | BL44: =BJ38-BL41 -> 6490.05 | BR44: =BP38-BR41 -> -2316.51

Sheet 2026
A1: JANEIRO | G1: FEVEREIRO | M1: MARÇO | S1: ABRIL | Y1: MAIO | AE1: JUNHO | AK1: JULHO | AQ1: AGOSTO | AW1: SETEMBRO | BC1: OUTUBRO | BI1: NOVEMBRO | BO1: DEZEMBRO
A2: Data | B2: Entrada | C2: Saída | D2: Diário | E2: Saldo | G2: Data | H2: Entrada | I2: Saída | J2: Diário | K2: Saldo | M2: Data | N2: Entrada | O2: Saída | P2: Diário | Q2: Saldo | S2: Data | T2: Entrada | U2: Saída | V2: Diário | W2: Saldo | Y2: Data | Z2: Entrada | AA2: Saída | AB2: Diário | AC2: Saldo | AE2: Data | AF2: Entrada | AG2: Saída | AH2: Diário | AI2: Saldo | AK2: Data | AL2: Entrada | AM2: Saída | AN2: Diário | AO2: Saldo | AQ2: Data | AR2: Entrada | AS2: Saída | AT2: Diário | AU2: Saldo | AW2: Data | AX2: Entrada | AY2: Saída | AZ2: Diário | BA2: Saldo | BC2: Data | BD2: Entrada | BE2: Saída | BF2: Diário | BG2: Saldo | BI2: Data | BJ2: Entrada | BK2: Saída | BL2: Diário | BM2: Saldo | BO2: Data | BP2: Entrada | BQ2: Saída | BR2: Diário | BS2: Saldo
A3: 1 | C3: =500 -> 500 | D3: =154.85 -> 154.85 | E3: ='2025'!BS33+(B3)-(C3+D3) -> 3518.69 | G3: 1 | I3: =500 -> 500 | J3: =154.85 -> 154.85 | K3: =(E33)+(H3)-(I3+J3) -> 7187.38 | M3: 1 | O3: =500 -> 500 | P3: =154.85 -> 154.85 | Q3: =(K33)+(N3)-(O3+P3) -> 11096.07 | S3: 1 | U3: =500 -> 500 | V3: =154.85 -> 154.85 | W3: =(Q33)+(T3)-(U3+V3) -> 15044.5 | Y3: 1 | AA3: =500 -> 500 | AB3: =154.85 -> 154.85 | AC3: =(W33)+(Z3)-(AA3+AB3) -> 19072.92 | AE3: 1 | AG3: =500 -> 500 | AH3: =154.85 -> 154.85 | AI3: =(AC33)+(AF3)-(AG3+AH3) -> 23434.5 | AK3: 1 | AM3: =500 -> 500 | AN3: =154.85 -> 154.85 | AO3: =(AI33)+(AL3)-(AM3+AN3) -> 27886.07 | AQ3: 1 | AS3: =500 -> 500 | AT3: =154.85 -> 154.85 | AU3: =(AO33)+(AR3)-(AS3+AT3) -> 32337.64 | AW3: 1 | AY3: =500 -> 500 | AZ3: =154.85 -> 154.85 | BA3: =(AU33)+(AX3)-(AY3+AZ3) -> 36852.89 | BC3: 1 | BE3: =500 -> 500 | BF3: =154.85 -> 154.85 | BG3: =(BA33)+(BD3)-(BE3+BF3) -> 41408.04 | BI3: 1 | BK3: =500 -> 500 | BL3: =154.85 -> 154.85 | BM3: =(BG33)+(BJ3)-(BK3+BL3) -> 45963.19 | BO3: 1 | BQ3: =500 -> 500 | BR3: =154.85 -> 154.85 | BS3: =(BM33)+(BP3)-(BQ3+BR3) -> 50685.35
A4: 2 | D4: =154.85 -> 154.85 | E4: =(E3)+(B4)-(C4+D4) -> 3363.84 | G4: 2 | J4: =154.85 -> 154.85 | K4: =(K3)+(H4)-(I4+J4) -> 7032.53 | M4: 2 | P4: =154.85 -> 154.85 | Q4: =(Q3)+(N4)-(O4+P4) -> 10941.22 | S4: 2 | V4: =154.85 -> 154.85 | W4: =(W3)+(T4)-(U4+V4) -> 14889.65 | Y4: 2 | AB4: =154.85 -> 154.85 | AC4: =(AC3)+(Z4)-(AA4+AB4) -> 18918.07 | AE4: 2 | AH4: =154.85 -> 154.85 | AI4: =(AI3)+(AF4)-(AG4+AH4) -> 23279.65 | AK4: 2 | AN4: =154.85 -> 154.85 | AO4: =(AO3)+(AL4)-(AM4+AN4) -> 27731.22 | AQ4: 2 | AT4: =154.85 -> 154.85 | AU4: =(AU3)+(AR4)-(AS4+AT4) -> 32182.79 | AW4: 2 | AZ4: =154.85 -> 154.85 | BA4: =(BA3)+(AX4)-(AY4+AZ4) -> 36698.04 | BC4: 2 | BF4: =154.85 -> 154.85 | BG4: =(BG3)+(BD4)-(BE4+BF4) -> 41253.19 | BI4: 2 | BL4: =154.85 -> 154.85 | BM4: =(BM3)+(BJ4)-(BK4+BL4) -> 45808.34 | BO4: 2 | BR4: =154.85 -> 154.85 | BS4: =(BS3)+(BP4)-(BQ4+BR4) -> 50530.5
A5: 3 | D5: =154.85 -> 154.85 | E5: =(E4)+(B5)-(C5+D5) -> 3208.99 | G5: 3 | J5: =154.85 -> 154.85 | K5: =(K4)+(H5)-(I5+J5) -> 6877.68 | M5: 3 | P5: =154.85 -> 154.85 | Q5: =(Q4)+(N5)-(O5+P5) -> 10786.37 | S5: 3 | V5: =154.85 -> 154.85 | W5: =(W4)+(T5)-(U5+V5) -> 14734.8 | Y5: 3 | AB5: =154.85 -> 154.85 | AC5: =(AC4)+(Z5)-(AA5+AB5) -> 18763.22 | AE5: 3 | AH5: =154.85 -> 154.85 | AI5: =(AI4)+(AF5)-(AG5+AH5) -> 23124.8 | AK5: 3 | AN5: =154.85 -> 154.85 | AO5: =(AO4)+(AL5)-(AM5+AN5) -> 27576.37 | AQ5: 3 | AT5: =154.85 -> 154.85 | AU5: =(AU4)+(AR5)-(AS5+AT5) -> 32027.94 | AW5: 3 | AZ5: =154.85 -> 154.85 | BA5: =(BA4)+(AX5)-(AY5+AZ5) -> 36543.19 | BC5: 3 | BF5: =154.85 -> 154.85 | BG5: =(BG4)+(BD5)-(BE5+BF5) -> 41098.34 | BI5: 3 | BL5: =154.85 -> 154.85 | BM5: =(BM4)+(BJ5)-(BK5+BL5) -> 45653.49 | BO5: 3 | BR5: =154.85 -> 154.85 | BS5: =(BS4)+(BP5)-(BQ5+BR5) -> 50375.65
A6: 4 | D6: =154.85 -> 154.85 | E6: =(E5)+(B6)-(C6+D6) -> 3054.14 | G6: 4 | J6: =154.85 -> 154.85 | K6: =(K5)+(H6)-(I6+J6) -> 6722.83 | M6: 4 | P6: =154.85 -> 154.85 | Q6: =(Q5)+(N6)-(O6+P6) -> 10631.52 | S6: 4 | V6: =154.85 -> 154.85 | W6: =(W5)+(T6)-(U6+V6) -> 14579.95 | Y6: 4 | AB6: =154.85 -> 154.85 | AC6: =(AC5)+(Z6)-(AA6+AB6) -> 18608.37 | AE6: 4 | AH6: =154.85 -> 154.85 | AI6: =(AI5)+(AF6)-(AG6+AH6) -> 22969.95 | AK6: 4 | AN6: =154.85 -> 154.85 | AO6: =(AO5)+(AL6)-(AM6+AN6) -> 27421.52 | AQ6: 4 | AT6: =154.85 -> 154.85 | AU6: =(AU5)+(AR6)-(AS6+AT6) -> 31873.09 | AW6: 4 | AZ6: =154.85 -> 154.85 | BA6: =(BA5)+(AX6)-(AY6+AZ6) -> 36388.34 | BC6: 4 | BF6: =154.85 -> 154.85 | BG6: =(BG5)+(BD6)-(BE6+BF6) -> 40943.49 | BI6: 4 | BL6: =154.85 -> 154.85 | BM6: =(BM5)+(BJ6)-(BK6+BL6) -> 45498.64 | BO6: 4 | BR6: =154.85 -> 154.85 | BS6: =(BS5)+(BP6)-(BQ6+BR6) -> 50220.8
A7: 5 | D7: =154.85 -> 154.85 | E7: =(E6)+(B7)-(C7+D7) -> 2899.29 | G7: 5 | J7: =154.85 -> 154.85 | K7: =(K6)+(H7)-(I7+J7) -> 6567.98 | M7: 5 | P7: =154.85 -> 154.85 | Q7: =(Q6)+(N7)-(O7+P7) -> 10476.67 | S7: 5 | V7: =154.85 -> 154.85 | W7: =(W6)+(T7)-(U7+V7) -> 14425.1 | Y7: 5 | AB7: =154.85 -> 154.85 | AC7: =(AC6)+(Z7)-(AA7+AB7) -> 18453.52 | AE7: 5 | AH7: =154.85 -> 154.85 | AI7: =(AI6)+(AF7)-(AG7+AH7) -> 22815.1 | AK7: 5 | AN7: =154.85 -> 154.85 | AO7: =(AO6)+(AL7)-(AM7+AN7) -> 27266.67 | AQ7: 5 | AT7: =154.85 -> 154.85 | AU7: =(AU6)+(AR7)-(AS7+AT7) -> 31718.24 | AW7: 5 | AZ7: =154.85 -> 154.85 | BA7: =(BA6)+(AX7)-(AY7+AZ7) -> 36233.49 | BC7: 5 | BF7: =154.85 -> 154.85 | BG7: =(BG6)+(BD7)-(BE7+BF7) -> 40788.64 | BI7: 5 | BL7: =154.85 -> 154.85 | BM7: =(BM6)+(BJ7)-(BK7+BL7) -> 45343.79 | BO7: 5 | BR7: =154.85 -> 154.85 | BS7: =(BS6)+(BP7)-(BQ7+BR7) -> 50065.95
A8: 6 | D8: =154.85 -> 154.85 | E8: =(E7)+(B8)-(C8+D8) -> 2744.44 | G8: 6 | J8: =154.85 -> 154.85 | K8: =(K7)+(H8)-(I8+J8) -> 6413.13 | M8: 6 | P8: =154.85 -> 154.85 | Q8: =(Q7)+(N8)-(O8+P8) -> 10321.82 | S8: 6 | V8: =154.85 -> 154.85 | W8: =(W7)+(T8)-(U8+V8) -> 14270.25 | Y8: 6 | AB8: =154.85 -> 154.85 | AC8: =(AC7)+(Z8)-(AA8+AB8) -> 18298.67 | AE8: 6 | AH8: =154.85 -> 154.85 | AI8: =(AI7)+(AF8)-(AG8+AH8) -> 22660.25 | AK8: 6 | AN8: =154.85 -> 154.85 | AO8: =(AO7)+(AL8)-(AM8+AN8) -> 27111.82 | AQ8: 6 | AT8: =154.85 -> 154.85 | AU8: =(AU7)+(AR8)-(AS8+AT8) -> 31563.39 | AW8: 6 | AZ8: =154.85 -> 154.85 | BA8: =(BA7)+(AX8)-(AY8+AZ8) -> 36078.64 | BC8: 6 | BF8: =154.85 -> 154.85 | BG8: =(BG7)+(BD8)-(BE8+BF8) -> 40633.79 | BI8: 6 | BL8: =154.85 -> 154.85 | BM8: =(BM7)+(BJ8)-(BK8+BL8) -> 45188.94 | BO8: 6 | BR8: =154.85 -> 154.85 | BS8: =(BS7)+(BP8)-(BQ8+BR8) -> 49911.1
A9: 7 | D9: =154.85 -> 154.85 | E9: =(E8)+(B9)-(C9+D9) -> 2589.59 | G9: 7 | J9: =154.85 -> 154.85 | K9: =(K8)+(H9)-(I9+J9) -> 6258.28 | M9: 7 | P9: =154.85 -> 154.85 | Q9: =(Q8)+(N9)-(O9+P9) -> 10166.97 | S9: 7 | V9: =154.85 -> 154.85 | W9: =(W8)+(T9)-(U9+V9) -> 14115.4 | Y9: 7 | AB9: =154.85 -> 154.85 | AC9: =(AC8)+(Z9)-(AA9+AB9) -> 18143.82 | AE9: 7 | AH9: =154.85 -> 154.85 | AI9: =(AI8)+(AF9)-(AG9+AH9) -> 22505.4 | AK9: 7 | AN9: =154.85 -> 154.85 | AO9: =(AO8)+(AL9)-(AM9+AN9) -> 26956.97 | AQ9: 7 | AT9: =154.85 -> 154.85 | AU9: =(AU8)+(AR9)-(AS9+AT9) -> 31408.54 | AW9: 7 | AZ9: =154.85 -> 154.85 | BA9: =(BA8)+(AX9)-(AY9+AZ9) -> 35923.79 | BC9: 7 | BF9: =154.85 -> 154.85 | BG9: =(BG8)+(BD9)-(BE9+BF9) -> 40478.94 | BI9: 7 | BL9: =154.85 -> 154.85 | BM9: =(BM8)+(BJ9)-(BK9+BL9) -> 45034.09 | BO9: 7 | BR9: =154.85 -> 154.85 | BS9: =(BS8)+(BP9)-(BQ9+BR9) -> 49756.25
A10: 8 | D10: =154.85 -> 154.85 | E10: =(E9)+(B10)-(C10+D10) -> 2434.74 | G10: 8 | J10: =154.85 -> 154.85 | K10: =(K9)+(H10)-(I10+J10) -> 6103.43 | M10: 8 | P10: =154.85 -> 154.85 | Q10: =(Q9)+(N10)-(O10+P10) -> 10012.12 | S10: 8 | V10: =154.85 -> 154.85 | W10: =(W9)+(T10)-(U10+V10) -> 13960.55 | Y10: 8 | AB10: =154.85 -> 154.85 | AC10: =(AC9)+(Z10)-(AA10+AB10) -> 17988.97 | AE10: 8 | AH10: =154.85 -> 154.85 | AI10: =(AI9)+(AF10)-(AG10+AH10) -> 22350.55 | AK10: 8 | AN10: =154.85 -> 154.85 | AO10: =(AO9)+(AL10)-(AM10+AN10) -> 26802.12 | AQ10: 8 | AT10: =154.85 -> 154.85 | AU10: =(AU9)+(AR10)-(AS10+AT10) -> 31253.69 | AW10: 8 | AZ10: =154.85 -> 154.85 | BA10: =(BA9)+(AX10)-(AY10+AZ10) -> 35768.94 | BC10: 8 | BF10: =154.85 -> 154.85 | BG10: =(BG9)+(BD10)-(BE10+BF10) -> 40324.09 | BI10: 8 | BL10: =154.85 -> 154.85 | BM10: =(BM9)+(BJ10)-(BK10+BL10) -> 44879.24 | BO10: 8 | BR10: =154.85 -> 154.85 | BS10: =(BS9)+(BP10)-(BQ10+BR10) -> 49601.4
A11: 9 | D11: =154.85 -> 154.85 | E11: =(E10)+(B11)-(C11+D11) -> 2279.89 | G11: 9 | J11: =154.85 -> 154.85 | K11: =(K10)+(H11)-(I11+J11) -> 5948.58 | M11: 9 | P11: =154.85 -> 154.85 | Q11: =(Q10)+(N11)-(O11+P11) -> 9857.27 | S11: 9 | V11: =154.85 -> 154.85 | W11: =(W10)+(T11)-(U11+V11) -> 13805.7 | Y11: 9 | AB11: =154.85 -> 154.85 | AC11: =(AC10)+(Z11)-(AA11+AB11) -> 17834.12 | AE11: 9 | AH11: =154.85 -> 154.85 | AI11: =(AI10)+(AF11)-(AG11+AH11) -> 22195.7 | AK11: 9 | AN11: =154.85 -> 154.85 | AO11: =(AO10)+(AL11)-(AM11+AN11) -> 26647.27 | AQ11: 9 | AT11: =154.85 -> 154.85 | AU11: =(AU10)+(AR11)-(AS11+AT11) -> 31098.84 | AW11: 9 | AZ11: =154.85 -> 154.85 | BA11: =(BA10)+(AX11)-(AY11+AZ11) -> 35614.09 | BC11: 9 | BF11: =154.85 -> 154.85 | BG11: =(BG10)+(BD11)-(BE11+BF11) -> 40169.24 | BI11: 9 | BL11: =154.85 -> 154.85 | BM11: =(BM10)+(BJ11)-(BK11+BL11) -> 44724.39 | BO11: 9 | BR11: =154.85 -> 154.85 | BS11: =(BS10)+(BP11)-(BQ11+BR11) -> 49446.55
A12: 10 | C12: =1881+100+160+60 -> 2201 | D12: =154.85 -> 154.85 | E12: =(E11)+(B12)-(C12+D12) -> -75.96 | G12: 10 | I12: =1881+100+160+60 -> 2201 | J12: =154.85 -> 154.85 | K12: =(K11)+(H12)-(I12+J12) -> 3592.73 | M12: 10 | O12: =1881+100+160+60 -> 2201 | P12: =154.85 -> 154.85 | Q12: =(Q11)+(N12)-(O12+P12) -> 7501.42 | S12: 10 | U12: =1881+100+160+60 -> 2201 | V12: =154.85 -> 154.85 | W12: =(W11)+(T12)-(U12+V12) -> 11449.85 | Y12: 10 | AA12: =1881+100+160+60 -> 2201 | AB12: =154.85 -> 154.85 | AC12: =(AC11)+(Z12)-(AA12+AB12) -> 15478.27 | AE12: 10 | AG12: =1881+100+160+60 -> 2201 | AH12: =154.85 -> 154.85 | AI12: =(AI11)+(AF12)-(AG12+AH12) -> 19839.85 | AK12: 10 | AM12: =1881+100+160+60 -> 2201 | AN12: =154.85 -> 154.85 | AO12: =(AO11)+(AL12)-(AM12+AN12) -> 24291.42 | AQ12: 10 | AS12: =1881+100+160+60 -> 2201 | AT12: =154.85 -> 154.85 | AU12: =(AU11)+(AR12)-(AS12+AT12) -> 28742.99 | AW12: 10 | AY12: =1881+100+160+60 -> 2201 | AZ12: =154.85 -> 154.85 | BA12: =(BA11)+(AX12)-(AY12+AZ12) -> 33258.24 | BC12: 10 | BE12: =1881+100+160+60 -> 2201 | BF12: =154.85 -> 154.85 | BG12: =(BG11)+(BD12)-(BE12+BF12) -> 37813.39 | BI12: 10 | BK12: =1881+100+160+60 -> 2201 | BL12: =154.85 -> 154.85 | BM12: =(BM11)+(BJ12)-(BK12+BL12) -> 42368.54 | BO12: 10 | BQ12: =1881+100+160+60 -> 2201 | BR12: =154.85 -> 154.85 | BS12: =(BS11)+(BP12)-(BQ12+BR12) -> 47090.7
A13: 11 | D13: =154.85 -> 154.85 | E13: =(E12)+(B13)-(C13+D13) -> -230.81 | G13: 11 | J13: =154.85 -> 154.85 | K13: =(K12)+(H13)-(I13+J13) -> 3437.88 | M13: 11 | P13: =154.85 -> 154.85 | Q13: =(Q12)+(N13)-(O13+P13) -> 7346.57 | S13: 11 | V13: =154.85 -> 154.85 | W13: =(W12)+(T13)-(U13+V13) -> 11295 | Y13: 11 | AB13: =154.85 -> 154.85 | AC13: =(AC12)+(Z13)-(AA13+AB13) -> 15323.42 | AE13: 11 | AH13: =154.85 -> 154.85 | AI13: =(AI12)+(AF13)-(AG13+AH13) -> 19685 | AK13: 11 | AN13: =154.85 -> 154.85 | AO13: =(AO12)+(AL13)-(AM13+AN13) -> 24136.57 | AQ13: 11 | AT13: =154.85 -> 154.85 | AU13: =(AU12)+(AR13)-(AS13+AT13) -> 28588.14 | AW13: 11 | AZ13: =154.85 -> 154.85 | BA13: =(BA12)+(AX13)-(AY13+AZ13) -> 33103.39 | BC13: 11 | BF13: =154.85 -> 154.85 | BG13: =(BG12)+(BD13)-(BE13+BF13) -> 37658.54 | BI13: 11 | BL13: =154.85 -> 154.85 | BM13: =(BM12)+(BJ13)-(BK13+BL13) -> 42213.69 | BO13: 11 | BR13: =154.85 -> 154.85 | BS13: =(BS12)+(BP13)-(BQ13+BR13) -> 46935.85
A14: 12 | D14: =154.85 -> 154.85 | E14: =(E13)+(B14)-(C14+D14) -> -385.66 | G14: 12 | J14: =154.85 -> 154.85 | K14: =(K13)+(H14)-(I14+J14) -> 3283.03 | M14: 12 | P14: =154.85 -> 154.85 | Q14: =(Q13)+(N14)-(O14+P14) -> 7191.72 | S14: 12 | V14: =154.85 -> 154.85 | W14: =(W13)+(T14)-(U14+V14) -> 11140.15 | Y14: 12 | AB14: =154.85 -> 154.85 | AC14: =(AC13)+(Z14)-(AA14+AB14) -> 15168.57 | AE14: 12 | AH14: =154.85 -> 154.85 | AI14: =(AI13)+(AF14)-(AG14+AH14) -> 19530.15 | AK14: 12 | AN14: =154.85 -> 154.85 | AO14: =(AO13)+(AL14)-(AM14+AN14) -> 23981.72 | AQ14: 12 | AT14: =154.85 -> 154.85 | AU14: =(AU13)+(AR14)-(AS14+AT14) -> 28433.29 | AW14: 12 | AZ14: =154.85 -> 154.85 | BA14: =(BA13)+(AX14)-(AY14+AZ14) -> 32948.54 | BC14: 12 | BF14: =154.85 -> 154.85 | BG14: =(BG13)+(BD14)-(BE14+BF14) -> 37503.69 | BI14: 12 | BL14: =154.85 -> 154.85 | BM14: =(BM13)+(BJ14)-(BK14+BL14) -> 42058.84 | BO14: 12 | BR14: =154.85 -> 154.85 | BS14: =(BS13)+(BP14)-(BQ14+BR14) -> 46781
A15: 13 | D15: =154.85 -> 154.85 | E15: =(E14)+(B15)-(C15+D15) -> -540.51 | G15: 13 | J15: =154.85 -> 154.85 | K15: =(K14)+(H15)-(I15+J15) -> 3128.18 | M15: 13 | P15: =154.85 -> 154.85 | Q15: =(Q14)+(N15)-(O15+P15) -> 7036.87 | S15: 13 | V15: =154.85 -> 154.85 | W15: =(W14)+(T15)-(U15+V15) -> 10985.3 | Y15: 13 | AB15: =154.85 -> 154.85 | AC15: =(AC14)+(Z15)-(AA15+AB15) -> 15013.72 | AE15: 13 | AH15: =154.85 -> 154.85 | AI15: =(AI14)+(AF15)-(AG15+AH15) -> 19375.3 | AK15: 13 | AN15: =154.85 -> 154.85 | AO15: =(AO14)+(AL15)-(AM15+AN15) -> 23826.87 | AQ15: 13 | AT15: =154.85 -> 154.85 | AU15: =(AU14)+(AR15)-(AS15+AT15) -> 28278.44 | AW15: 13 | AZ15: =154.85 -> 154.85 | BA15: =(BA14)+(AX15)-(AY15+AZ15) -> 32793.69 | BC15: 13 | BF15: =154.85 -> 154.85 | BG15: =(BG14)+(BD15)-(BE15+BF15) -> 37348.84 | BI15: 13 | BL15: =154.85 -> 154.85 | BM15: =(BM14)+(BJ15)-(BK15+BL15) -> 41903.99 | BO15: 13 | BR15: =154.85 -> 154.85 | BS15: =(BS14)+(BP15)-(BQ15+BR15) -> 46626.15
A16: 14 | D16: =154.85 -> 154.85 | E16: =(E15)+(B16)-(C16+D16) -> -695.36 | G16: 14 | J16: =154.85 -> 154.85 | K16: =(K15)+(H16)-(I16+J16) -> 2973.33 | M16: 14 | P16: =154.85 -> 154.85 | Q16: =(Q15)+(N16)-(O16+P16) -> 6882.02 | S16: 14 | V16: =154.85 -> 154.85 | W16: =(W15)+(T16)-(U16+V16) -> 10830.45 | Y16: 14 | AB16: =154.85 -> 154.85 | AC16: =(AC15)+(Z16)-(AA16+AB16) -> 14858.87 | AE16: 14 | AH16: =154.85 -> 154.85 | AI16: =(AI15)+(AF16)-(AG16+AH16) -> 19220.45 | AK16: 14 | AN16: =154.85 -> 154.85 | AO16: =(AO15)+(AL16)-(AM16+AN16) -> 23672.02 | AQ16: 14 | AT16: =154.85 -> 154.85 | AU16: =(AU15)+(AR16)-(AS16+AT16) -> 28123.59 | AW16: 14 | AZ16: =154.85 -> 154.85 | BA16: =(BA15)+(AX16)-(AY16+AZ16) -> 32638.84 | BC16: 14 | BF16: =154.85 -> 154.85 | BG16: =(BG15)+(BD16)-(BE16+BF16) -> 37193.99 | BI16: 14 | BL16: =154.85 -> 154.85 | BM16: =(BM15)+(BJ16)-(BK16+BL16) -> 41749.14 | BO16: 14 | BR16: =154.85 -> 154.85 | BS16: =(BS15)+(BP16)-(BQ16+BR16) -> 46471.3
A17: 15 | C17: =500 -> 500 | D17: =154.85 -> 154.85 | E17: =(E16)+(B17)-(C17+D17) -> -1350.21 | G17: 15 | I17: =500 -> 500 | J17: =154.85 -> 154.85 | K17: =(K16)+(H17)-(I17+J17) -> 2318.48 | M17: 15 | O17: =500 -> 500 | P17: =154.85 -> 154.85 | Q17: =(Q16)+(N17)-(O17+P17) -> 6227.17 | S17: 15 | U17: =500 -> 500 | V17: =154.85 -> 154.85 | W17: =(W16)+(T17)-(U17+V17) -> 10175.6 | Y17: 15 | AA17: =500 -> 500 | AB17: =154.85 -> 154.85 | AC17: =(AC16)+(Z17)-(AA17+AB17) -> 14204.02 | AE17: 15 | AG17: =500 -> 500 | AH17: =154.85 -> 154.85 | AI17: =(AI16)+(AF17)-(AG17+AH17) -> 18565.6 | AK17: 15 | AM17: =500 -> 500 | AN17: =154.85 -> 154.85 | AO17: =(AO16)+(AL17)-(AM17+AN17) -> 23017.17 | AQ17: 15 | AS17: =500 -> 500 | AT17: =154.85 -> 154.85 | AU17: =(AU16)+(AR17)-(AS17+AT17) -> 27468.74 | AW17: 15 | AY17: =500 -> 500 | AZ17: =154.85 -> 154.85 | BA17: =(BA16)+(AX17)-(AY17+AZ17) -> 31983.99 | BC17: 15 | BE17: =500 -> 500 | BF17: =154.85 -> 154.85 | BG17: =(BG16)+(BD17)-(BE17+BF17) -> 36539.14 | BI17: 15 | BK17: =500 -> 500 | BL17: =154.85 -> 154.85 | BM17: =(BM16)+(BJ17)-(BK17+BL17) -> 41094.29 | BO17: 15 | BQ17: =500 -> 500 | BR17: =154.85 -> 154.85 | BS17: =(BS16)+(BP17)-(BQ17+BR17) -> 45816.45
A18: 16 | D18: =154.85 -> 154.85 | E18: =(E17)+(B18)-(C18+D18) -> -1505.06 | G18: 16 | J18: =154.85 -> 154.85 | K18: =(K17)+(H18)-(I18+J18) -> 2163.63 | M18: 16 | P18: =154.85 -> 154.85 | Q18: =(Q17)+(N18)-(O18+P18) -> 6072.32 | S18: 16 | V18: =154.85 -> 154.85 | W18: =(W17)+(T18)-(U18+V18) -> 10020.75 | Y18: 16 | AB18: =154.85 -> 154.85 | AC18: =(AC17)+(Z18)-(AA18+AB18) -> 14049.17 | AE18: 16 | AH18: =154.85 -> 154.85 | AI18: =(AI17)+(AF18)-(AG18+AH18) -> 18410.75 | AK18: 16 | AN18: =154.85 -> 154.85 | AO18: =(AO17)+(AL18)-(AM18+AN18) -> 22862.32 | AQ18: 16 | AT18: =154.85 -> 154.85 | AU18: =(AU17)+(AR18)-(AS18+AT18) -> 27313.89 | AW18: 16 | AZ18: =154.85 -> 154.85 | BA18: =(BA17)+(AX18)-(AY18+AZ18) -> 31829.14 | BC18: 16 | BF18: =154.85 -> 154.85 | BG18: =(BG17)+(BD18)-(BE18+BF18) -> 36384.29 | BI18: 16 | BL18: =154.85 -> 154.85 | BM18: =(BM17)+(BJ18)-(BK18+BL18) -> 40939.44 | BO18: 16 | BR18: =154.85 -> 154.85 | BS18: =(BS17)+(BP18)-(BQ18+BR18) -> 45661.6
A19: 17 | D19: =154.85 -> 154.85 | E19: =(E18)+(B19)-(C19+D19) -> -1659.91 | G19: 17 | J19: =154.85 -> 154.85 | K19: =(K18)+(H19)-(I19+J19) -> 2008.78 | M19: 17 | P19: =154.85 -> 154.85 | Q19: =(Q18)+(N19)-(O19+P19) -> 5917.47 | S19: 17 | V19: =154.85 -> 154.85 | W19: =(W18)+(T19)-(U19+V19) -> 9865.9 | Y19: 17 | AB19: =154.85 -> 154.85 | AC19: =(AC18)+(Z19)-(AA19+AB19) -> 13894.32 | AE19: 17 | AH19: =154.85 -> 154.85 | AI19: =(AI18)+(AF19)-(AG19+AH19) -> 18255.9 | AK19: 17 | AN19: =154.85 -> 154.85 | AO19: =(AO18)+(AL19)-(AM19+AN19) -> 22707.47 | AQ19: 17 | AT19: =154.85 -> 154.85 | AU19: =(AU18)+(AR19)-(AS19+AT19) -> 27159.04 | AW19: 17 | AZ19: =154.85 -> 154.85 | BA19: =(BA18)+(AX19)-(AY19+AZ19) -> 31674.29 | BC19: 17 | BF19: =154.85 -> 154.85 | BG19: =(BG18)+(BD19)-(BE19+BF19) -> 36229.44 | BI19: 17 | BL19: =154.85 -> 154.85 | BM19: =(BM18)+(BJ19)-(BK19+BL19) -> 40784.59 | BO19: 17 | BR19: =154.85 -> 154.85 | BS19: =(BS18)+(BP19)-(BQ19+BR19) -> 45506.75
A20: 18 | D20: =154.85 -> 154.85 | E20: =(E19)+(B20)-(C20+D20) -> -1814.76 | G20: 18 | J20: =154.85 -> 154.85 | K20: =(K19)+(H20)-(I20+J20) -> 1853.93 | M20: 18 | P20: =154.85 -> 154.85 | Q20: =(Q19)+(N20)-(O20+P20) -> 5762.62 | S20: 18 | V20: =154.85 -> 154.85 | W20: =(W19)+(T20)-(U20+V20) -> 9711.05 | Y20: 18 | AB20: =154.85 -> 154.85 | AC20: =(AC19)+(Z20)-(AA20+AB20) -> 13739.47 | AE20: 18 | AH20: =154.85 -> 154.85 | AI20: =(AI19)+(AF20)-(AG20+AH20) -> 18101.05 | AK20: 18 | AN20: =154.85 -> 154.85 | AO20: =(AO19)+(AL20)-(AM20+AN20) -> 22552.62 | AQ20: 18 | AT20: =154.85 -> 154.85 | AU20: =(AU19)+(AR20)-(AS20+AT20) -> 27004.19 | AW20: 18 | AZ20: =154.85 -> 154.85 | BA20: =(BA19)+(AX20)-(AY20+AZ20) -> 31519.44 | BC20: 18 | BF20: =154.85 -> 154.85 | BG20: =(BG19)+(BD20)-(BE20+BF20) -> 36074.59 | BI20: 18 | BL20: =154.85 -> 154.85 | BM20: =(BM19)+(BJ20)-(BK20+BL20) -> 40629.74 | BO20: 18 | BR20: =154.85 -> 154.85 | BS20: =(BS19)+(BP20)-(BQ20+BR20) -> 45351.9
A21: 19 | D21: =154.85 -> 154.85 | E21: =(E20)+(B21)-(C21+D21) -> -1969.61 | G21: 19 | J21: =154.85 -> 154.85 | K21: =(K20)+(H21)-(I21+J21) -> 1699.08 | M21: 19 | P21: =154.85 -> 154.85 | Q21: =(Q20)+(N21)-(O21+P21) -> 5607.77 | S21: 19 | V21: =154.85 -> 154.85 | W21: =(W20)+(T21)-(U21+V21) -> 9556.2 | Y21: 19 | AB21: =154.85 -> 154.85 | AC21: =(AC20)+(Z21)-(AA21+AB21) -> 13584.62 | AE21: 19 | AH21: =154.85 -> 154.85 | AI21: =(AI20)+(AF21)-(AG21+AH21) -> 17946.2 | AK21: 19 | AN21: =154.85 -> 154.85 | AO21: =(AO20)+(AL21)-(AM21+AN21) -> 22397.77 | AQ21: 19 | AT21: =154.85 -> 154.85 | AU21: =(AU20)+(AR21)-(AS21+AT21) -> 26849.34 | AW21: 19 | AZ21: =154.85 -> 154.85 | BA21: =(BA20)+(AX21)-(AY21+AZ21) -> 31364.59 | BC21: 19 | BF21: =154.85 -> 154.85 | BG21: =(BG20)+(BD21)-(BE21+BF21) -> 35919.74 | BI21: 19 | BL21: =154.85 -> 154.85 | BM21: =(BM20)+(BJ21)-(BK21+BL21) -> 40474.89 | BO21: 19 | BR21: =154.85 -> 154.85 | BS21: =(BS20)+(BP21)-(BQ21+BR21) -> 45197.05
A22: 20 | D22: =154.85 -> 154.85 | E22: =(E21)+(B22)-(C22+D22) -> -2124.46 | G22: 20 | J22: =154.85 -> 154.85 | K22: =(K21)+(H22)-(I22+J22) -> 1544.23 | M22: 20 | P22: =154.85 -> 154.85 | Q22: =(Q21)+(N22)-(O22+P22) -> 5452.92 | S22: 20 | V22: =154.85 -> 154.85 | W22: =(W21)+(T22)-(U22+V22) -> 9401.35 | Y22: 20 | AB22: =154.85 -> 154.85 | AC22: =(AC21)+(Z22)-(AA22+AB22) -> 13429.77 | AE22: 20 | AH22: =154.85 -> 154.85 | AI22: =(AI21)+(AF22)-(AG22+AH22) -> 17791.35 | AK22: 20 | AN22: =154.85 -> 154.85 | AO22: =(AO21)+(AL22)-(AM22+AN22) -> 22242.92 | AQ22: 20 | AT22: =154.85 -> 154.85 | AU22: =(AU21)+(AR22)-(AS22+AT22) -> 26694.49 | AW22: 20 | AZ22: =154.85 -> 154.85 | BA22: =(BA21)+(AX22)-(AY22+AZ22) -> 31209.74 | BC22: 20 | BF22: =154.85 -> 154.85 | BG22: =(BG21)+(BD22)-(BE22+BF22) -> 35764.89 | BI22: 20 | BL22: =154.85 -> 154.85 | BM22: =(BM21)+(BJ22)-(BK22+BL22) -> 40320.04 | BO22: 20 | BR22: =154.85 -> 154.85 | BS22: =(BS21)+(BP22)-(BQ22+BR22) -> 45042.2
A23: 21 | B23: 17800 | D23: =154.85 -> 154.85 | E23: =(E22)+(B23)-(C23+D23) -> 15520.69 | G23: 21 | H23: 17800 | J23: =154.85 -> 154.85 | K23: =(K22)+(H23)-(I23+J23) -> 19189.38 | M23: 21 | N23: 17800 | P23: =154.85 -> 154.85 | Q23: =(Q22)+(N23)-(O23+P23) -> 23098.07 | S23: 21 | T23: 17800 | V23: =154.85 -> 154.85 | W23: =(W22)+(T23)-(U23+V23) -> 27046.5 | Y23: 21 | Z23: 17800 | AB23: =154.85 -> 154.85 | AC23: =(AC22)+(Z23)-(AA23+AB23) -> 31074.92 | AE23: 21 | AF23: 17800 | AH23: =154.85 -> 154.85 | AI23: =(AI22)+(AF23)-(AG23+AH23) -> 35436.5 | AK23: 21 | AL23: 17800 | AN23: =154.85 -> 154.85 | AO23: =(AO22)+(AL23)-(AM23+AN23) -> 39888.07 | AQ23: 21 | AR23: 17800 | AT23: =154.85 -> 154.85 | AU23: =(AU22)+(AR23)-(AS23+AT23) -> 44339.64 | AW23: 21 | AX23: 17800 | AZ23: =154.85 -> 154.85 | BA23: =(BA22)+(AX23)-(AY23+AZ23) -> 48854.89 | BC23: 21 | BD23: 17800 | BF23: =154.85 -> 154.85 | BG23: =(BG22)+(BD23)-(BE23+BF23) -> 53410.04 | BI23: 21 | BJ23: 17800 | BL23: =154.85 -> 154.85 | BM23: =(BM22)+(BJ23)-(BK23+BL23) -> 57965.19 | BO23: 21 | BP23: 17800 | BR23: =154.85 -> 154.85 | BS23: =(BS22)+(BP23)-(BQ23+BR23) -> 62687.35
A24: 22 | D24: =154.85 -> 154.85 | E24: =(E23)+(B24)-(C24+D24) -> 15365.84 | G24: 22 | J24: =154.85 -> 154.85 | K24: =(K23)+(H24)-(I24+J24) -> 19034.53 | M24: 22 | P24: =154.85 -> 154.85 | Q24: =(Q23)+(N24)-(O24+P24) -> 22943.22 | S24: 22 | V24: =154.85 -> 154.85 | W24: =(W23)+(T24)-(U24+V24) -> 26891.65 | Y24: 22 | AB24: =154.85 -> 154.85 | AC24: =(AC23)+(Z24)-(AA24+AB24) -> 30920.07 | AE24: 22 | AH24: =154.85 -> 154.85 | AI24: =(AI23)+(AF24)-(AG24+AH24) -> 35281.65 | AK24: 22 | AN24: =154.85 -> 154.85 | AO24: =(AO23)+(AL24)-(AM24+AN24) -> 39733.22 | AQ24: 22 | AT24: =154.85 -> 154.85 | AU24: =(AU23)+(AR24)-(AS24+AT24) -> 44184.79 | AW24: 22 | AZ24: =154.85 -> 154.85 | BA24: =(BA23)+(AX24)-(AY24+AZ24) -> 48700.04 | BC24: 22 | BF24: =154.85 -> 154.85 | BG24: =(BG23)+(BD24)-(BE24+BF24) -> 53255.19 | BI24: 22 | BL24: =154.85 -> 154.85 | BM24: =(BM23)+(BJ24)-(BK24+BL24) -> 57810.34 | BO24: 22 | BR24: =154.85 -> 154.85 | BS24: =(BS23)+(BP24)-(BQ24+BR24) -> 62532.5
A25: 23 | C25: =178.69+379.8 -> 558.49 | D25: =154.85 -> 154.85 | E25: =(E24)+(B25)-(C25+D25) -> 14652.5 | G25: 23 | I25: =178.69+379.8 -> 558.49 | J25: =154.85 -> 154.85 | K25: =(K24)+(H25)-(I25+J25) -> 18321.19 | M25: 23 | O25: =178.69+379.8 -> 558.49 | P25: =154.85 -> 154.85 | Q25: =(Q24)+(N25)-(O25+P25) -> 22229.88 | S25: 23 | U25: =178.69+379.8 -> 558.49 | V25: =154.85 -> 154.85 | W25: =(W24)+(T25)-(U25+V25) -> 26178.31 | Y25: 23 | AA25: =178.69+379.8 -> 558.49 | AB25: =154.85 -> 154.85 | AC25: =(AC24)+(Z25)-(AA25+AB25) -> 30206.73 | AE25: 23 | AG25: =178.69+379.8 -> 558.49 | AH25: =154.85 -> 154.85 | AI25: =(AI24)+(AF25)-(AG25+AH25) -> 34568.31 | AK25: 23 | AM25: =178.69+379.8 -> 558.49 | AN25: =154.85 -> 154.85 | AO25: =(AO24)+(AL25)-(AM25+AN25) -> 39019.88 | AQ25: 23 | AS25: =178.69+379.8 -> 558.49 | AT25: =154.85 -> 154.85 | AU25: =(AU24)+(AR25)-(AS25+AT25) -> 43471.45 | AW25: 23 | AY25: =178.69+379.8 -> 558.49 | AZ25: =154.85 -> 154.85 | BA25: =(BA24)+(AX25)-(AY25+AZ25) -> 47986.7 | BC25: 23 | BE25: =178.69+379.8 -> 558.49 | BF25: =154.85 -> 154.85 | BG25: =(BG24)+(BD25)-(BE25+BF25) -> 52541.85 | BI25: 23 | BK25: =178.69+379.8 -> 558.49 | BL25: =154.85 -> 154.85 | BM25: =(BM24)+(BJ25)-(BK25+BL25) -> 57097 | BO25: 23 | BQ25: =178.69+379.8 -> 558.49 | BR25: =154.85 -> 154.85 | BS25: =(BS24)+(BP25)-(BQ25+BR25) -> 61819.16
A26: 24 | C26: =167.01+553.3+333.16 -> 1053.47 | D26: =154.85 -> 154.85 | E26: =(E25)+(B26)-(C26+D26) -> 13444.18 | G26: 24 | I26: =167.01+313.3+333.16 -> 813.47 | J26: =154.85 -> 154.85 | K26: =(K25)+(H26)-(I26+J26) -> 17352.87 | M26: 24 | O26: =167.01+273.56+333.16 -> 773.73 | P26: =154.85 -> 154.85 | Q26: =(Q25)+(N26)-(O26+P26) -> 21301.3 | S26: 24 | U26: =167.01+193.57+333.16 -> 693.74 | V26: =154.85 -> 154.85 | W26: =(W25)+(T26)-(U26+V26) -> 25329.72 | Y26: 24 | AA26: =167.01+193.57 -> 360.58 | AB26: =154.85 -> 154.85 | AC26: =(AC25)+(Z26)-(AA26+AB26) -> 29691.3 | AE26: 24 | AG26: =167.01+103.58 -> 270.59 | AH26: =154.85 -> 154.85 | AI26: =(AI25)+(AF26)-(AG26+AH26) -> 34142.87 | AK26: 24 | AM26: =167.01+103.58 -> 270.59 | AN26: =154.85 -> 154.85 | AO26: =(AO25)+(AL26)-(AM26+AN26) -> 38594.44 | AQ26: 24 | AS26: =167.01+39.9 -> 206.91 | AT26: =154.85 -> 154.85 | AU26: =(AU25)+(AR26)-(AS26+AT26) -> 43109.69 | AW26: 24 | AY26: 167.01 | AZ26: =154.85 -> 154.85 | BA26: =(BA25)+(AX26)-(AY26+AZ26) -> 47664.84 | BC26: 24 | BE26: 167.01 | BF26: =154.85 -> 154.85 | BG26: =(BG25)+(BD26)-(BE26+BF26) -> 52219.99 | BI26: 24 | BL26: =154.85 -> 154.85 | BM26: =(BM25)+(BJ26)-(BK26+BL26) -> 56942.15 | BO26: 24 | BR26: =154.85 -> 154.85 | BS26: =(BS25)+(BP26)-(BQ26+BR26) -> 61664.31
A27: 25 | D27: =154.85 -> 154.85 | E27: =(E26)+(B27)-(C27+D27) -> 13289.33 | G27: 25 | J27: =154.85 -> 154.85 | K27: =(K26)+(H27)-(I27+J27) -> 17198.02 | M27: 25 | P27: =154.85 -> 154.85 | Q27: =(Q26)+(N27)-(O27+P27) -> 21146.45 | S27: 25 | V27: =154.85 -> 154.85 | W27: =(W26)+(T27)-(U27+V27) -> 25174.87 | Y27: 25 | AB27: =154.85 -> 154.85 | AC27: =(AC26)+(Z27)-(AA27+AB27) -> 29536.45 | AE27: 25 | AH27: =154.85 -> 154.85 | AI27: =(AI26)+(AF27)-(AG27+AH27) -> 33988.02 | AK27: 25 | AN27: =154.85 -> 154.85 | AO27: =(AO26)+(AL27)-(AM27+AN27) -> 38439.59 | AQ27: 25 | AT27: =154.85 -> 154.85 | AU27: =(AU26)+(AR27)-(AS27+AT27) -> 42954.84 | AW27: 25 | AZ27: =154.85 -> 154.85 | BA27: =(BA26)+(AX27)-(AY27+AZ27) -> 47509.99 | BC27: 25 | BF27: =154.85 -> 154.85 | BG27: =(BG26)+(BD27)-(BE27+BF27) -> 52065.14 | BI27: 25 | BL27: =154.85 -> 154.85 | BM27: =(BM26)+(BJ27)-(BK27+BL27) -> 56787.3 | BO27: 25 | BR27: =154.85 -> 154.85 | BS27: =(BS26)+(BP27)-(BQ27+BR27) -> 61509.46
A28: 26 | C28: =4230+103+30+110+45 -> 4518 | D28: =154.85 -> 154.85 | E28: =(E27)+(B28)-(C28+D28) -> 8616.48 | G28: 26 | I28: =4230+103+30+110+45 -> 4518 | J28: =154.85 -> 154.85 | K28: =(K27)+(H28)-(I28+J28) -> 12525.17 | M28: 26 | O28: =4230+103+30+110+45 -> 4518 | P28: =154.85 -> 154.85 | Q28: =(Q27)+(N28)-(O28+P28) -> 16473.6 | S28: 26 | U28: =4230+103+30+110+45 -> 4518 | V28: =154.85 -> 154.85 | W28: =(W27)+(T28)-(U28+V28) -> 20502.02 | Y28: 26 | AA28: =4230+103+30+110+45 -> 4518 | AB28: =154.85 -> 154.85 | AC28: =(AC27)+(Z28)-(AA28+AB28) -> 24863.6 | AE28: 26 | AG28: =4230+103+30+110+45 -> 4518 | AH28: =154.85 -> 154.85 | AI28: =(AI27)+(AF28)-(AG28+AH28) -> 29315.17 | AK28: 26 | AM28: =4230+103+30+110+45 -> 4518 | AN28: =154.85 -> 154.85 | AO28: =(AO27)+(AL28)-(AM28+AN28) -> 33766.74 | AQ28: 26 | AS28: =4230+103+30+110+45 -> 4518 | AT28: =154.85 -> 154.85 | AU28: =(AU27)+(AR28)-(AS28+AT28) -> 38281.99 | AW28: 26 | AY28: =4230+103+30+110+45 -> 4518 | AZ28: =154.85 -> 154.85 | BA28: =(BA27)+(AX28)-(AY28+AZ28) -> 42837.14 | BC28: 26 | BE28: =4230+103+30+110+45 -> 4518 | BF28: =154.85 -> 154.85 | BG28: =(BG27)+(BD28)-(BE28+BF28) -> 47392.29 | BI28: 26 | BK28: =4230+103+30+110+45 -> 4518 | BL28: =154.85 -> 154.85 | BM28: =(BM27)+(BJ28)-(BK28+BL28) -> 52114.45 | BO28: 26 | BQ28: =4230+103+30+110+45 -> 4518 | BR28: =154.85 -> 154.85 | BS28: =(BS27)+(BP28)-(BQ28+BR28) -> 56836.61
A29: 27 | D29: =154.85 -> 154.85 | E29: =(E28)+(B29)-(C29+D29) -> 8461.63 | G29: 27 | J29: =154.85 -> 154.85 | K29: =(K28)+(H29)-(I29+J29) -> 12370.32 | M29: 27 | P29: =154.85 -> 154.85 | Q29: =(Q28)+(N29)-(O29+P29) -> 16318.75 | S29: 27 | V29: =154.85 -> 154.85 | W29: =(W28)+(T29)-(U29+V29) -> 20347.17 | Y29: 27 | AB29: =154.85 -> 154.85 | AC29: =(AC28)+(Z29)-(AA29+AB29) -> 24708.75 | AE29: 27 | AH29: =154.85 -> 154.85 | AI29: =(AI28)+(AF29)-(AG29+AH29) -> 29160.32 | AK29: 27 | AN29: =154.85 -> 154.85 | AO29: =(AO28)+(AL29)-(AM29+AN29) -> 33611.89 | AQ29: 27 | AT29: =154.85 -> 154.85 | AU29: =(AU28)+(AR29)-(AS29+AT29) -> 38127.14 | AW29: 27 | AZ29: =154.85 -> 154.85 | BA29: =(BA28)+(AX29)-(AY29+AZ29) -> 42682.29 | BC29: 27 | BF29: =154.85 -> 154.85 | BG29: =(BG28)+(BD29)-(BE29+BF29) -> 47237.44 | BI29: 27 | BL29: =154.85 -> 154.85 | BM29: =(BM28)+(BJ29)-(BK29+BL29) -> 51959.6 | BO29: 27 | BR29: =154.85 -> 154.85 | BS29: =(BS28)+(BP29)-(BQ29+BR29) -> 56681.76
A30: 28 | D30: =154.85 -> 154.85 | E30: =(E29)+(B30)-(C30+D30) -> 8306.78 | G30: 28 | J30: =154.85 -> 154.85 | K30: =(K29)+(H30)-(I30+J30) -> 12215.47 | M30: 28 | P30: =154.85 -> 154.85 | Q30: =(Q29)+(N30)-(O30+P30) -> 16163.9 | S30: 28 | V30: =154.85 -> 154.85 | W30: =(W29)+(T30)-(U30+V30) -> 20192.32 | Y30: 28 | AB30: =154.85 -> 154.85 | AC30: =(AC29)+(Z30)-(AA30+AB30) -> 24553.9 | AE30: 28 | AH30: =154.85 -> 154.85 | AI30: =(AI29)+(AF30)-(AG30+AH30) -> 29005.47 | AK30: 28 | AN30: =154.85 -> 154.85 | AO30: =(AO29)+(AL30)-(AM30+AN30) -> 33457.04 | AQ30: 28 | AT30: =154.85 -> 154.85 | AU30: =(AU29)+(AR30)-(AS30+AT30) -> 37972.29 | AW30: 28 | AZ30: =154.85 -> 154.85 | BA30: =(BA29)+(AX30)-(AY30+AZ30) -> 42527.44 | BC30: 28 | BF30: =154.85 -> 154.85 | BG30: =(BG29)+(BD30)-(BE30+BF30) -> 47082.59 | BI30: 28 | BL30: =154.85 -> 154.85 | BM30: =(BM29)+(BJ30)-(BK30+BL30) -> 51804.75 | BO30: 28 | BR30: =154.85 -> 154.85 | BS30: =(BS29)+(BP30)-(BQ30+BR30) -> 56526.91
A31: 29 | D31: =154.85 -> 154.85 | E31: =(E30)+(B31)-(C31+D31) -> 8151.93 | G31: 29 | J31: =154.85 -> 154.85 | K31: =(K30)+(H31)-(I31+J31) -> 12060.62 | M31: 29 | P31: =154.85 -> 154.85 | Q31: =(Q30)+(N31)-(O31+P31) -> 16009.05 | S31: 29 | V31: =154.85 -> 154.85 | W31: =(W30)+(T31)-(U31+V31) -> 20037.47 | Y31: 29 | AB31: =154.85 -> 154.85 | AC31: =(AC30)+(Z31)-(AA31+AB31) -> 24399.05 | AE31: 29 | AH31: =154.85 -> 154.85 | AI31: =(AI30)+(AF31)-(AG31+AH31) -> 28850.62 | AK31: 29 | AN31: =154.85 -> 154.85 | AO31: =(AO30)+(AL31)-(AM31+AN31) -> 33302.19 | AQ31: 29 | AT31: =154.85 -> 154.85 | AU31: =(AU30)+(AR31)-(AS31+AT31) -> 37817.44 | AW31: 29 | AZ31: =154.85 -> 154.85 | BA31: =(BA30)+(AX31)-(AY31+AZ31) -> 42372.59 | BC31: 29 | BF31: =154.85 -> 154.85 | BG31: =(BG30)+(BD31)-(BE31+BF31) -> 46927.74 | BI31: 29 | BL31: =154.85 -> 154.85 | BM31: =(BM30)+(BJ31)-(BK31+BL31) -> 51649.9 | BO31: 29 | BR31: =154.85 -> 154.85 | BS31: =(BS30)+(BP31)-(BQ31+BR31) -> 56372.06
A32: 30 | D32: =154.85 -> 154.85 | E32: =(E31)+(B32)-(C32+D32) -> 7997.08 | G32: 30 | J32: =154.85 -> 154.85 | K32: =(K31)+(H32)-(I32+J32) -> 11905.77 | M32: 30 | P32: =154.85 -> 154.85 | Q32: =(Q31)+(N32)-(O32+P32) -> 15854.2 | S32: 30 | V32: =154.85 -> 154.85 | W32: =(W31)+(T32)-(U32+V32) -> 19882.62 | Y32: 30 | AB32: =154.85 -> 154.85 | AC32: =(AC31)+(Z32)-(AA32+AB32) -> 24244.2 | AE32: 30 | AH32: =154.85 -> 154.85 | AI32: =(AI31)+(AF32)-(AG32+AH32) -> 28695.77 | AK32: 30 | AN32: =154.85 -> 154.85 | AO32: =(AO31)+(AL32)-(AM32+AN32) -> 33147.34 | AQ32: 30 | AT32: =154.85 -> 154.85 | AU32: =(AU31)+(AR32)-(AS32+AT32) -> 37662.59 | AW32: 30 | AZ32: =154.85 -> 154.85 | BA32: =(BA31)+(AX32)-(AY32+AZ32) -> 42217.74 | BC32: 30 | BF32: =154.85 -> 154.85 | BG32: =(BG31)+(BD32)-(BE32+BF32) -> 46772.89 | BI32: 30 | BL32: =154.85 -> 154.85 | BM32: =(BM31)+(BJ32)-(BK32+BL32) -> 51495.05 | BO32: 30 | BR32: =154.85 -> 154.85 | BS32: =(BS31)+(BP32)-(BQ32+BR32) -> 56217.21
A33: 31 | D33: =154.85 -> 154.85 | E33: =(E32)+(B33)-(C33+D33) -> 7842.23 | G33: 31 | J33: =154.85 -> 154.85 | K33: =(K32)+(H33)-(I33+J33) -> 11750.92 | M33: 31 | P33: =154.85 -> 154.85 | Q33: =(Q32)+(N33)-(O33+P33) -> 15699.35 | S33: 31 | V33: =154.85 -> 154.85 | W33: =(W32)+(T33)-(U33+V33) -> 19727.77 | Y33: 31 | AB33: =154.85 -> 154.85 | AC33: =(AC32)+(Z33)-(AA33+AB33) -> 24089.35 | AE33: 31 | AH33: =154.85 -> 154.85 | AI33: =(AI32)+(AF33)-(AG33+AH33) -> 28540.92 | AK33: 31 | AN33: =154.85 -> 154.85 | AO33: =(AO32)+(AL33)-(AM33+AN33) -> 32992.49 | AQ33: 31 | AT33: =154.85 -> 154.85 | AU33: =(AU32)+(AR33)-(AS33+AT33) -> 37507.74 | AW33: 31 | AZ33: =154.85 -> 154.85 | BA33: =(BA32)+(AX33)-(AY33+AZ33) -> 42062.89 | BC33: 31 | BF33: =154.85 -> 154.85 | BG33: =(BG32)+(BD33)-(BE33+BF33) -> 46618.04 | BI33: 31 | BL33: =154.85 -> 154.85 | BM33: =(BM32)+(BJ33)-(BK33+BL33) -> 51340.2 | BO33: 31 | BR33: =154.85 -> 154.85 | BS33: =(BS32)+(BP33)-(BQ33+BR33) -> 56062.36
B37: ENTRADAS | C37: SAÍDAS | D37: DIÁRIO | H37: ENTRADAS | I37: SAÍDAS | J37: DIÁRIO | N37: ENTRADAS | O37: SAÍDAS | P37: DIÁRIO | T37: ENTRADAS | U37: SAÍDAS | V37: DIÁRIO | Z37: ENTRADAS | AA37: SAÍDAS | AB37: DIÁRIO | AF37: ENTRADAS | AG37: SAÍDAS | AH37: DIÁRIO | AL37: ENTRADAS | AM37: SAÍDAS | AN37: DIÁRIO | AR37: ENTRADAS | AS37: SAÍDAS | AT37: DIÁRIO | AX37: ENTRADAS | AY37: SAÍDAS | AZ37: DIÁRIO | BD37: ENTRADAS | BE37: SAÍDAS | BF37: DIÁRIO | BJ37: ENTRADAS | BK37: SAÍDAS | BL37: DIÁRIO | BP37: ENTRADAS | BQ37: SAÍDAS | BR37: DIÁRIO
B38: =SUM(B3:B33) -> 17800 | C38: =SUM(C3:C33) -> 9330.96 | D38: =SUM(D3:D33) -> 4800.35 | E38: =E34 | H38: =SUM(H3:H33) -> 17800 | I38: =SUM(I3:I33) -> 9090.96 | J38: =SUM(J3:J33) -> 4800.35 | K38: =K34 | N38: =SUM(N3:N33) -> 17800 | O38: =SUM(O3:O33) -> 9051.22 | P38: =SUM(P3:P33) -> 4800.35 | Q38: =Q34 | T38: =SUM(T3:T33) -> 17800 | U38: =SUM(U3:U33) -> 8971.23 | V38: =SUM(V3:V33) -> 4800.35 | W38: =W34 | Z38: =SUM(Z3:Z33) -> 17800 | AA38: =SUM(AA3:AA33) -> 8638.07 | AB38: =SUM(AB3:AB33) -> 4800.35 | AC38: =AC34 | AF38: =SUM(AF3:AF33) -> 17800 | AG38: =SUM(AG3:AG33) -> 8548.08 | AH38: =SUM(AH3:AH33) -> 4800.35 | AI38: =AI34 | AL38: =SUM(AL3:AL33) -> 17800 | AM38: =SUM(AM3:AM33) -> 8548.08 | AN38: =SUM(AN3:AN33) -> 4800.35 | AO38: =AO34 | AR38: =SUM(AR3:AR33) -> 17800 | AS38: =SUM(AS3:AS33) -> 8484.4 | AT38: =SUM(AT3:AT33) -> 4800.35 | AU38: =AU34 | AX38: =SUM(AX3:AX33) -> 17800 | AY38: =SUM(AY3:AY33) -> 8444.5 | AZ38: =SUM(AZ3:AZ33) -> 4800.35 | BA38: =BA34 | BD38: =SUM(BD3:BD33) -> 17800 | BE38: =SUM(BE3:BE33) -> 8444.5 | BF38: =SUM(BF3:BF33) -> 4800.35 | BG38: =BG34 | BJ38: =SUM(BJ3:BJ33) -> 17800 | BK38: =SUM(BK3:BK33) -> 8277.49 | BL38: =SUM(BL3:BL33) -> 4800.35 | BM38: =BM34 | BP38: =SUM(BP3:BP33) -> 17800 | BQ38: =SUM(BQ3:BQ33) -> 8277.49 | BR38: =SUM(BR3:BR33) -> 4800.35 | BS38: =BS34
D40: Saída Total | J40: Saída Total | P40: Saída Total | V40: Saída Total | AB40: Saída Total | AH40: Saída Total | AN40: Saída Total | AT40: Saída Total | AZ40: Saída Total | BF40: Saída Total | BL40: Saída Total | BR40: Saída Total
D41: =C38+D38 -> 14131.31 | J41: =I38+J38 -> 13891.31 | P41: =O38+P38 -> 13851.57 | V41: =U38+V38 -> 13771.58 | AB41: =AA38+AB38 -> 13438.42 | AH41: =AG38+AH38 -> 13348.43 | AN41: =AM38+AN38 -> 13348.43 | AT41: =AS38+AT38 -> 13284.75 | AZ41: =AY38+AZ38 -> 13244.85 | BF41: =BE38+BF38 -> 13244.85 | BL41: =BK38+BL38 -> 13077.84 | BR41: =BQ38+BR38 -> 13077.84
D43: Performance | J43: Performance | P43: Performance | V43: Performance | AB43: Performance | AH43: Performance | AN43: Performance | AT43: Performance | AZ43: Performance | BF43: Performance | BL43: Performance | BR43: Performance
D44: =B38-D41 -> 3668.69 | J44: =H38-J41 -> 3908.69 | P44: =N38-P41 -> 3948.43 | V44: =T38-V41 -> 4028.42 | AB44: =Z38-AB41 -> 4361.58 | AH44: =AF38-AH41 -> 4451.57 | AN44: =AL38-AN41 -> 4451.57 | AT44: =AR38-AT41 -> 4515.25 | AZ44: =AX38-AZ41 -> 4555.15 | BF44: =BD38-BF41 -> 4555.15 | BL44: =BJ38-BL41 -> 4722.16 | BR44: =BP38-BR41 -> 4722.16

Sheet Economia
B4: 2025 | C4: Entradas | D4: Economia | E4: % | G4: 2026 | H4: Entradas | I4: Economia | J4: %
B5: jan | C5: ='2025'!B38 -> 0 | D5: 0 | E5: =D5/C5 -> #DIV/0! | G5: jan | H5: ='2026'!B38 -> 17800 | I5: 0 | J5: =I5/H5 -> 0
B6: fev | C6: ='2025'!H38 -> 0 | D6: 0 | E6: =D6/C6 -> #DIV/0! | G6: fev | H6: ='2026'!H38 -> 17800 | I6: 0 | J6: =I6/H6 -> 0
B7: mar | C7: ='2025'!N38 -> 0 | D7: 0 | E7: =D7/C7 -> #DIV/0! | G7: mar | H7: ='2026'!N38 -> 17800 | I7: 0 | J7: =I7/H7 -> 0
B8: abr | C8: ='2025'!T38 -> 0 | D8: 0 | E8: =D8/C8 -> #DIV/0! | G8: abr | H8: ='2026'!T38 -> 17800 | I8: 0 | J8: =I8/H8 -> 0
B9: mai | C9: ='2025'!Z38 -> 0 | D9: 0 | E9: =D9/C9 -> #DIV/0! | G9: mai | H9: ='2026'!Z38 -> 17800 | I9: 0 | J9: =I9/H9 -> 0
